Workbook

Sheet 交付概览
A2: 保险条款采集累计交付台账
A3: 更新日期 | B3: 46321 | D3: D1–B28累计259条限定工单，阶段全审97份4250页。网站v126／索引v102已回验。
A5: D1–B14内容基线（保留） | B5: 数量 | C5: 单位 | D5: 验收边界
A6: 地区基线 | B6: =COUNTA('12地区基线'!A2:A13) -> 12 | C6: 个地区 | D6: 已列出范围。未核实的地区统计保持空白。
A7: 保司与来源索引 | B7: =COUNTA(保司与来源!A2:A243) -> 242 | C7: 条来源 | D7: 原有201条来源完整保留，追加B7–B14共41条。不是保司数或独立产品数。
A8: 十四批冻结任务基数 | B8: =SUM(B29:B30,B55:B58,B77:B84) -> 108 | C8: 条任务 | D8: D1–B6历史67条；B7–B14追加41条。各批冻结基数不随缺失行缩减。
A9: D1–B14任务行数 | B9: =COUNTA(首批固定任务!A2:A109) -> 108 | C9: 条任务 | D9: 按任务 ID 计，不是独立产品数或新取得文件数。
A10: D1–B14处理记录 | B10: =COUNTA(本批执行结果!A2:A109) -> 108 | C10: 条任务 | D10: 108条是限定证据工单。B10变体线索与B13/B14重复目标探测不增加独立产品。
A11: D1–B14证据验收 | B11: =COUNTIFS(本批执行结果!M2:M109,"已验收") -> 108 | C11: 条任务 | D11: 需要复核通过、证据、有效日期及范围匹配。并非产品齐备数。
A12: D1–B14现存页全审 | B12: =SUMIFS(本批执行结果!F2:F109,本批执行结果!M2:M109,"已验收") -> 45 | C12: 份文件 | D12: 累计45份既存原件、1243物理页全审；含通用组件和非合同说明，不等于45套产品合同。
A13: 目标主文缺口关闭 | B13: =SUMIFS(本批执行结果!H2:H109,本批执行结果!M2:M109,"已验收") -> 0 | C13: 项 | D13: 各批目标主文／独立产品缺口新增关闭均0。独立产品分母未核定，不计算市场覆盖率。
A14: D1期初任务单位 | B14: 条数 | C14: 单位 | D14: 说明
A15: 产品路线核验 | B15: =COUNTIFS(首批固定任务!F2:F13,A15) -> 4 | C15: 条任务 | D15: 香港固定 4 个产品路线。可交付明确缺口，不等于已取得主文。
A16: 产品组件核验 | B16: =COUNTIFS(首批固定任务!F2:F13,A16) -> 1 | C16: 条任务 | D16: 核 Travel Protector 的现行 COVID-19 扩展／批单。
A17: 产品版本核验 | B17: =COUNTIFS(首批固定任务!F2:F13,A17) -> 1 | C17: 条任务 | D17: 核 Home Protector 360 06/20 采用关系，不代入 Basic。
A18: 文档核验 | B18: =COUNTIFS(首批固定任务!F2:F13,A18) -> 6 | C18: 条任务 | D18: 新加坡 1 份页序核验，马来西亚 5 份 Master 文档共 114 页。
A20: 历史存量（非本批新增）
A21: 指标 | B21: 历史数量 | C21: 单位 | D21: 口径
A22: 原件 | B22: =SUM('12地区基线'!D2:D13) -> 4710 | C22: 份文件 | D22: v89 历史存量，含公开原件 4,659 与隔离文件 51。
A23: 已全文审阅 | B23: =SUM('12地区基线'!E2:E13) -> 2245 | C23: 份文件 | D23: v89 历史全文审阅数量，不代表全市场覆盖。
A24: 严格通过 | B24: =SUM('12地区基线'!F2:F13) -> 411 | C24: 份文件 | D24: v89 严格主文文件数，不是 411 个完整产品。
A25: 隔离文件 | B25: =SUM('12地区基线'!G2:G13) -> 51 | C25: 份文件 | D25: v89 保留隔离文件，属于历史原件，不与原件再相加。
A27: 分批冻结与验收
A28: 批次 | B28: 冻结任务 | C28: 证据验收 | D28: 分批边界
A29: D1首批 | B29: 12 | C29: =COUNTIFS(本批执行结果!N2:N24,"D1",本批执行结果!M2:M24,"已验收") -> 12 | D29: 期初12条／验收0。现增5份全审114页及3份支持原件，均已发布。
A30: B2第二批 | B30: 11 | C30: =COUNTIFS(本批执行结果!N2:N24,"B2",本批执行结果!M2:M24,"已验收") -> 11 | D30: 期初11条／验收0。新增6份全审205页、主文角色4份已发布，合同问题仍待核。
A31: D1+B2历史累计 | B31: =SUM(B29:B30) -> 23 | C31: =SUM(C29:C30) -> 23 | D31: 只汇总证据交付。首批不重复计数，受阻与未完成范围不删除。
A33: 累计增量与未解项 | B33: 数量 | C33: 单位 | D33: 说明
A34: D1–B14全审页数 | B34: =SUMIFS(本批执行结果!P2:P109,本批执行结果!M2:M109,"已验收") -> 1243 | C34: 页 | D34: 1243页仅为现存文件全页审读。EASYCare视觉32页、Traveller英文13页及ID18页部分审读不混入。
A35: 新增支持原件 | B35: =SUMIFS(本批执行结果!E2:E109,本批执行结果!M2:M109,"已验收") -> 3 | C35: 份 | D35: 仅D1取得3份支持原件；B2–B14新增原件均0。
A36: 严格通过新增 | B36: =SUMIFS(本批执行结果!G2:G109,本批执行结果!M2:M109,"已验收") -> 3 | C36: 份 | D36: 文件级严格净增3：B8两份、B12 PA Direct一份。与当前采用、个人齐套及产品闭合分别计。
A37: 语言依赖未解 | B37: =SUMIFS(本批执行结果!R2:R109,本批执行结果!M2:M109,"已验收") -> 3 | C37: 份 | D37: EASYCare／Traveller高棉语及ID优先印尼语语义等未解决；有限任务完成不消除语言依赖。
A38: B2新增主文角色 | B38: =SUMIFS(本批执行结果!Q2:Q24,本批执行结果!M2:M24,"已验收") -> 4 | C38: 份 | D38: 4份文件角色已确认，但均仍待核验，不计产品齐套。
A40: 发布与固定索引 | B40: 数量 | C40: 单位 | D40: 状态与口径
A41: 已发布正式原件 | B41: 4713 | C41: 份 | D41: 网站v126／私有索引v102；正式4713、公开4662、隔离51不变。
A42: 其中公开原件 | B42: 4662 | C42: 份 | D42: 公开原件4,662，隔离文件51。两者合计4,713。
A43: 已发布全文审阅 | B43: 2342 | C43: 份 | D43: 当前全文2342；B28新增全文0，阶段97份4250页不变。
A44: B2已发布全文增量 | B44: =SUMIFS(本批执行结果!F2:F24,本批执行结果!N2:N24,"B2",本批执行结果!M2:M24,"已验收") -> 6 | C44: 份 | D44: 新增6份已进入线上版本115。网站已更新第二批核验状态；原件与详审证据私有留存。
A45: 第三批已验收任务 | B45: 10 | C45: 项 | D45: 10项限定任务已验收并发布：5份全文184页，2路线、2历史关系、1英文部分审读。
A46: 范围与重复报警 | B46: =MAX(COUNTIFS(本批执行结果!S2:S109,"缺范围或重复"),B8-COUNTA(首批固定任务!A2:A109),B8-COUNTA(本批执行结果!A2:A109),0) -> 0 | C46: 项 | D46: 必须为0。缺少冻结范围、重复任务或缺失执行记录均须检查。
...

Sheet 本批执行结果
A1: 任务ID | B1: 地区 | C1: 处理状态 | D1: 本批结论 | E1: 新支持材料 | F1: 现存页全文核验 | G1: 严格新增 | H1: 缺口关闭 | I1: 复核状态 | J1: 复核证据 | K1: 处理完成日 | L1: 后续动作 | M1: 验收判定 | N1: 批次 | O1: 保司 | P1: 新增全文页数 | Q1: 新增主文角色 | R1: 语言依赖未解 | S1: 范围匹配 | T1: 内容状态 | U1: 新增原件 | V1: 文件角色／审读范围 | W1: 产品主文可得性 | X1: 当前公开合同包 | Y1: 当前采用／现售 | Z1: 来源证据类型 | AA1: 重要边界 | AB1: 原始文件／族ID
A2: D1-HK-001 | B2: 香港 | C2: 已复核 | D2: 官方页及产品册集中库只见宣传册；BEA专属产品页仅链接产品册。BEA册第16物理页排除合同角色，第23页列银行版本。10Life具体场景页未见文档下载链接。 | E2: 1 | F2: 0 | G2: 0 | H2: 0 | I2: 通过 | J2: 公开路线及支持件角色/SHA已复核；准确既有产品下正式新增1份银行宣传册（未全文），完整主文仍未取得，现存页全文/严格通过/缺口关闭增量0。 | K2: 46321 | L2: 取得用户提供的匿名官方保单样本，或经另外明确授权后向AIA索取准确版次样本；若出现独立公开同族主文URL可继续定点查验。 | M2: =IF(S2<>"匹配","缺范围任务",IF(I2="通过",IF(AND(J2<>"",ISNUMBER(K2),K2>=DATE(2026,10,26)),"已验收","缺证据或日期"),IF(I2="","缺状态","待复核"))) -> 已验收 | N2: D1 | O2: AIA 友邦香港 | P2: 0 | Q2: 0 | R2: 0 | S2: =IF(AND(A2<>"",N2<>"",COUNTIFS(首批固定任务!$A$2:$A$109,A2,首批固定任务!$N$2:$N$109,N2)=1,COUNTIFS($A$2:$A$109,A2)=1),"匹配","缺范围或重复") -> 匹配 | T2: 保留首批内容结论，不代表产品齐备 | U2: =E2 -> 1 | V2: 沿用D1/B2已验收结论 | W2: 沿用D1/B2结论，不新增推断 | X2: 未认定齐备 | Y2: 未由本次更新确认 | Z2: D1/B2冻结验收历史 | AA2: 新增列仅分层说明；原有任务结论与来源不覆盖。 | AB2: aia-simply-love-encore-5
A3: D1-HK-002 | B3: 香港 | C3: 已复核 | D3: 官网只提供产品册和Policy Services册；表格库未见本族主文。服务册的具体服务条款不能当整份主合同，SHA与基线相同。10Life命中Elite场景标签，不将其当独立合同版次或泛化覆盖。另查新发现的DBS独立产品页，普通访问返回403后停止；不表示所有公开来源已穷尽。 | E3: 0 | F3: 0 | G3: 0 | H3: 0 | I3: 通过 | J3: 公开路线处理证据及支持件角色/SHA已复核；完整主文未取得，未补齐产品，正式原件／现存页全审／严格通过增量均0。 | K3: 46321 | L3: 保持该受限入口停止。仅在获得新的公开主文入口或明确授权索取准确官方样本后继续。 | M3: =IF(S3<>"匹配","缺范围任务",IF(I3="通过",IF(AND(J3<>"",ISNUMBER(K3),K3>=DATE(2026,10,26)),"已验收","缺证据或日期"),IF(I3="","缺状态","待复核"))) -> 已验收 | N3: D1 | O3: Manulife 宏利香港 | P3: 0 | Q3: 0 | R3: 0 | S3: =IF(AND(A3<>"",N3<>"",COUNTIFS(首批固定任务!$A$2:$A$109,A3,首批固定任务!$N$2:$N$109,N3)=1,COUNTIFS($A$2:$A$109,A3)=1),"匹配","缺范围或重复") -> 匹配 | T3: 保留首批内容结论，不代表产品齐备 | U3: =E3 -> 0 | V3: 沿用D1/B2已验收结论 | W3: 沿用D1/B2结论，不新增推断 | X3: 未认定齐备 | Y3: 未由本次更新确认 | Z3: D1/B2冻结验收历史 | AA3: 新增列仅分层说明；原有任务结论与来源不覆盖。 | AB3: manulife-goldenstart
A4: D1-HK-003 | B4: 香港 | C4: 已复核 | D4: 中英官网确认产品名、承保主体及样本须另索取；下载库仅服务/理赔表，未见本族主文。复用昨日SC目录定点定位本族册链接，今日取得48物理页银行册；鷹宇公开介绍未见主文附件。 | E4: 1 | F4: 0 | G4: 0 | H4: 0 | I4: 通过 | J4: 公开路线及支持件角色/SHA已复核；准确既有产品下正式新增1份银行宣传册（未全文），完整主文仍未取得，现存页全文/严格通过/缺口关闭增量0。 | K4: 46321 | L4: 取得准确PHOR版次的官方匿名保单样本，或另外明确授权向Prudential索取；保留香港与澳门版本隔离。 | M4: =IF(S4<>"匹配","缺范围任务",IF(I4="通过",IF(AND(J4<>"",ISNUMBER(K4),K4>=DATE(2026,10,26)),"已验收","缺证据或日期"),IF(I4="","缺状态","待复核"))) -> 已验收 | N4: D1 | O4: Prudential 保诚香港 | P4: 0 | Q4: 0 | R4: 0 | S4: =IF(AND(A4<>"",N4<>"",COUNTIFS(首批固定任务!$A$2:$A$109,A4,首批固定任务!$N$2:$N$109,N4)=1,COUNTIFS($A$2:$A$109,A4)=1),"匹配","缺范围或重复") -> 匹配 | T4: 保留首批内容结论，不代表产品齐备 | U4: =E4 -> 1 | V4: 沿用D1/B2已验收结论 | W4: 沿用D1/B2结论，不新增推断 | X4: 未认定齐备 | Y4: 未由本次更新确认 | Z4: D1/B2冻结验收历史 | AA4: 新增列仅分层说明；原有任务结论与来源不覆盖。 | AB4: prudential-prime-horizon-insurance-plan
A5: D1-HK-004 | B5: 香港 | C5: 已复核 | D5: 官网及Find a form未见本族主文；大新专页只提供产品册；本地公开介绍链接亦为产品册。大新册第23页说明非保险合同且样本应要求提供。 | E5: 1 | F5: 0 | G5: 0 | H5: 0 | I5: 通过 | J5: 公开路线及支持件角色/SHA已复核；准确既有产品下正式新增1份银行宣传册（未全文），完整主文仍未取得，现存页全文/严格通过/缺口关闭增量0。 | K5: 46321 | L5: 取得Sun Life发出的匿名保单文件样本，或另外明确授权索取；当前公开册不能代替准确合同版本。 | M5: =IF(S5<>"匹配","缺范围任务",IF(I5="通过",IF(AND(J5<>"",ISNUMBER(K5),K5>=DATE(2026,10,26)),"已验收","缺证据或日期"),IF(I5="","缺状态","待复核"))) -> 已验收 | N5: D1 | O5: Sun Life 永明香港 | P5: 0 | Q5: 0 | R5: 0 | S5: =IF(AND(A5<>"",N5<>"",COUNTIFS(首批固定任务!$A$2:$A$109,A5,首批固定任务!$N$2:$N$109,N5)=1,COUNTIFS($A$2:$A$109,A5)=1),"匹配","缺范围或重复") -> 匹配 | T5: 保留首批内容结论，不代表产品齐备 | U5: =E5 -> 1 | V5: 沿用D1/B2已验收结论 | W5: 沿用D1/B2结论，不新增推断 | X5: 未认定齐备 | Y5: 未由本次更新确认 | Z5: D1/B2冻结验收历史 | AA5: 新增列仅分层说明；原有任务结论与来源不覆盖。 | AB5: sunlife-royalfortune
A6: D1-SG-001 | B6: 新加坡 | C6: 已复核 | D6: 现行官方目录、SingSaver与Marsh公开销售页均核过。SingSaver当前链接所得26页主文与既有2024基准原件同SHA；Marsh也链接同一官方主文。新增两条采用/渠道关系，不新增原件或全文；1026册40–48项COVID扩展仍未取得，合同包未齐。 | E6: 0 | F6: 0 | G6: 0 | H6: 0 | I6: 通过 | J6: 同SHA26页基准主文复用；新增2条渠道链接关系，COVID批单仍缺；正式原件／现存页全审／严格通过增量0。 | K6: 46321 | L6: 待用户提供或另行授权取得现行明确采用的COVID扩展/批单；不得用旧候选、宣传册或基础主文推定补齐。 | M6: =IF(S6<>"匹配","缺范围任务",IF(I6="通过",IF(AND(J6<>"",ISNUMBER(K6),K6>=DATE(2026,10,26)),"已验收","缺证据或日期"),IF(I6="","缺状态","待复核"))) -> 已验收 | N6: D1 | O6: Allied World Assurance Company, Ltd (Singapore Branch) | P6: 0 | Q6: 0 | R6: 0 | S6: =IF(AND(A6<>"",N6<>"",COUNTIFS(首批固定任务!$A$2:$A$109,A6,首批固定任务!$N$2:$N$109,N6)=1,COUNTIFS($A$2:$A$109,A6)=1),"匹配","缺范围或重复") -> 匹配 | T6: 保留首批内容结论，不代表产品齐备 | U6: =E6 -> 0 | V6: 沿用D1/B2已验收结论 | W6: 沿用D1/B2结论，不新增推断 | X6: 未认定齐备 | Y6: 未由本次更新确认 | Z6: D1/B2冻结验收历史 | AA6: 新增列仅分层说明；原有任务结论与来源不覆盖。 | AB6: SG-F-c279cfe77714176e
A7: D1-SG-002 | B7: 新加坡 | C7: 已复核 | D7: 当前官方页仍分别链接0326的360和Basic宣传册。既有360册四页无06/20准确主文链接或采用声明；名称、表列利益相似及官网资产可检索不等于版次采用。未找到替代主文或准确采用证据；360与Basic保持隔离。 | E7: 0 | F7: 0 | G7: 0 | H7: 0 | I7: 通过 | J7: 21页06/20既有主文复用；现行采用未证，Basic隔离；正式原件／现存页全审／严格通过增量0。 | K7: 46321 | L7: 待精确采用声明、现行主文包或独立Basic正文证据；现有360全文记录保留但不升级现行家族覆盖。 | M7: =IF(S7<>"匹配","缺范围任务",IF(I7="通过",IF(AND(J7<>"",ISNUMBER(K7),K7>=DATE(2026,10,26)),"已验收","缺证据或日期"),IF(I7="","缺状态","待复核"))) -> 已验收 | N7: D1 | O7: Allied World Assurance Company, Ltd (Singapore Branch) | P7: 0 | Q7: 0 | R7: 0 | S7: =IF(AND(A7<>"",N7<>"",COUNTIFS(首批固定任务!$A$2:$A$109,A7,首批固定任务!$N$2:$N$109,N7)=1,COUNTIFS($A$2:$A$109,A7)=1),"匹配","缺范围或重复") -> 匹配 | T7: 保留首批内容结论，不代表产品齐备 | U7: =E7 -> 0 | V7: 沿用D1/B2已验收结论 | W7: 沿用D1/B2结论，不新增推断 | X7: 未认定齐备 | Y7: 未由本次更新确认 | Z7: D1/B2冻结验收历史 | AA7: 新增列仅分层说明；原有任务结论与来源不覆盖。 | AB7: SG-F-14656bec56df8d86
A8: D1-SG-003 | B8: 新加坡 | C8: 已复核 | D8: 本地原件SHA复验一致，21物理页逐页页码与版式复核；正文2–20连续，34项目录定位均吻合，3.16投诉在20页正常收尾后为封底。内部未见跳号不等于已证完整：页脚总数24仍未获出版者解释，维持候选/完整性未核，不推定缺3页。官方当前文库普通GET返回403后停止。 | E8: 0 | F8: 0 | G8: 0 | H8: 0 | I8: 通过 | J8: 21物理页及34目录项定位通过；页脚总数24疑点未解；既有全文审阅完成、家族主文不计入、仍待核验不变，现存页全审增量0。 | K8: 46321 | L8: 仅在获得公开出版者同版勘误、明确新原件或用户提供权威说明后再解除页序疑点；未授权外联/登录前保持受阻。 | M8: =IF(S8<>"匹配","缺范围任务",IF(I8="通过",IF(AND(J8<>"",ISNUMBER(K8),K8>=DATE(2026,10,26)),"已验收","缺证据或日期"),IF(I8="","缺状态","待复核"))) -> 已验收 | N8: D1 | O8: Utmost Worldwide Limited (Singapore Branch) | P8: 0 | Q8: 0 | R8: 0 | S8: =IF(AND(A8<>"",N8<>"",COUNTIFS(首批固定任务!$A$2:$A$109,A8,首批固定任务!$N$2:$N$109,N8)=1,COUNTIFS($A$2:$A$109,A8)=1),"匹配","缺范围或重复") -> 匹配 | T8: 保留首批内容结论，不代表产品齐备 | U8: =E8 -> 0 | V8: 沿用D1/B2已验收结论 | W8: 沿用D1/B2结论，不新增推断 | X8: 未认定齐备 | Y8: 未由本次更新确认 | Z8: D1/B2冻结验收历史 | AA8: 新增列仅分层说明；原有任务结论与来源不覆盖。 | AB8: SG-4330cfac28a50f2e
A9: D1-MY-001 | B9: 马来西亚 | C9: 已复核 | D9: 已逐页审读24页。保费表印页2未见；其标准或个别化性质未定。主体及主保单身份已辨识，当前采用未证，不升严格通过。 | E9: 0 | F9: 1 | G9: 0 | H9: 0 | I9: 通过 | J9: 原件SHA、物理页与逐页文字/视觉证据核对通过；现存页全文核验+1（合计5份114页），合同完整性仍待核、合同完整未确认、严格通过增量0；不要求真实个人专属附表。 | K9: 46321 | L9: 核实精确公开采用证据及附表性质，不索取真实客户私人资料。 | M9: =IF(S9<>"匹配","缺范围任务",IF(I9="通过",IF(AND(J9<>"",ISNUMBER(K9),K9>=DATE(2026,10,26)),"已验收","缺证据或日期"),IF(I9="","缺状态","待复核"))) -> 已验收 | N9: D1 | O9: Sun Life Malaysia Assurance Berhad | P9: 24 | Q9: 0 | R9: 0 | S9: =IF(AND(A9<>"",N9<>"",COUNTIFS(首批固定任务!$A$2:$A$109,A9,首批固定任务!$N$2:$N$109,N9)=1,COUNTIFS($A$2:$A$109,A9)=1),"匹配","缺范围或重复") -> 匹配 | T9: 保留首批内容结论，不代表产品齐备 | U9: =E9 -> 0 | V9: 沿用D1/B2已验收结论 | W9: 沿用D1/B2结论，不新增推断 | X9: 未认定齐备 | Y9: 未由本次更新确认 | Z9: D1/B2冻结验收历史 | AA9: 新增列仅分层说明；原有任务结论与来源不覆盖。 | AB9: MY-SUN-005
A10: D1-MY-002 | B10: 马来西亚 | C10: 已复核 | D10: 已逐页审读37页双语内容。BIZS001主保单表未见，角色仍待区分；不能据页码跳跃断言通用保障条文缺失。当前渠道采用未证。 | E10: 0 | F10: 1 | G10: 0 | H10: 0 | I10: 通过 | J10: 原件SHA、物理页与逐页文字/视觉证据核对通过；现存页全文核验+1（合计5份114页），合同完整性仍待核、合同完整未确认、严格通过增量0；不要求真实个人专属附表。 | K10: 46321 | L10: 核实精确公开采用证据及附表性质，不索取真实客户私人资料。 | M10: =IF(S10<>"匹配","缺范围任务",IF(I10="通过",IF(AND(J10<>"",ISNUMBER(K10),K10>=DATE(2026,10,26)),"已验收","缺证据或日期"),IF(I10="","缺状态","待复核"))) -> 已验收 | N10: D1 | O10: Sun Life Malaysia Assurance Berhad | P10: 37 | Q10: 0 | R10: 0 | S10: =IF(AND(A10<>"",N10<>"",COUNTIFS(首批固定任务!$A$2:$A$109,A10,首批固定任务!$N$2:$N$109,N10)=1,COUNTIFS($A$2:$A$109,A10)=1),"匹配","缺范围或重复") -> 匹配 | T10: 保留首批内容结论，不代表产品齐备 | U10: =E10 -> 0 | V10: 沿用D1/B2已验收结论 | W10: 沿用D1/B2结论，不新增推断 | X10: 未认定齐备 | Y10: 未由本次更新确认 | Z10: D1/B2冻结验收历史 | AA10: 新增列仅分层说明；原有任务结论与来源不覆盖。 | AB10: MY-SUN-002
A11: D1-MY-003 | B11: 马来西亚 | C11: 已复核 | D11: 已逐页审读14页。GTTAD001/003/004/005在件；GTTAD002未见，性质未定。活动标签并不证明正文采用或当前销售。 | E11: 0 | F11: 1 | G11: 0 | H11: 0 | I11: 通过 | J11: 原件SHA、物理页与逐页文字/视觉证据核对通过；现存页全文核验+1（合计5份114页），合同完整性仍待核、合同完整未确认、严格通过增量0；不要求真实个人专属附表。 | K11: 46321 | L11: 核实精确公开采用证据及附表性质，不索取真实客户私人资料。 | M11: =IF(S11<>"匹配","缺范围任务",IF(I11="通过",IF(AND(J11<>"",ISNUMBER(K11),K11>=DATE(2026,10,26)),"已验收","缺证据或日期"),IF(I11="","缺状态","待复核"))) -> 已验收 | N11: D1 | O11: Sun Life Malaysia Takaful Berhad | P11: 14 | Q11: 0 | R11: 0 | S11: =IF(AND(A11<>"",N11<>"",COUNTIFS(首批固定任务!$A$2:$A$109,A11,首批固定任务!$N$2:$N$109,N11)=1,COUNTIFS($A$2:$A$109,A11)=1),"匹配","缺范围或重复") -> 匹配 | T11: 保留首批内容结论，不代表产品齐备 | U11: =E11 -> 0 | V11: 沿用D1/B2已验收结论 | W11: 沿用D1/B2结论，不新增推断 | X11: 未认定齐备 | Y11: 未由本次更新确认 | Z11: D1/B2冻结验收历史 | AA11: 新增列仅分层说明；原有任务结论与来源不覆盖。 | AB11: MY-SUN-029
A12: D1-MY-004 | B12: 马来西亚 | C12: 已复核 | D12: 已逐页审读13页，印页1–12连续；GTT002是已包含的保障表，公开标准正文完整。具体活动采用与当前可用性仍未证。 | E12: 0 | F12: 1 | G12: 0 | H12: 0 | I12: 通过 | J12: 原件SHA、物理页与逐页文字/视觉证据核对通过；现存页全文核验+1（合计5份114页），合同完整性仍待核、合同完整未确认、严格通过增量0；不要求真实个人专属附表。 | K12: 46321 | L12: 核实精确公开采用证据及附表性质，不索取真实客户私人资料。 | M12: =IF(S12<>"匹配","缺范围任务",IF(I12="通过",IF(AND(J12<>"",ISNUMBER(K12),K12>=DATE(2026,10,26)),"已验收","缺证据或日期"),IF(I12="","缺状态","待复核"))) -> 已验收 | N12: D1 | O12: Sun Life Malaysia Takaful Berhad | P12: 13 | Q12: 0 | R12: 0 | S12: =IF(AND(A12<>"",N12<>"",COUNTIFS(首批固定任务!$A$2:$A$109,A12,首批固定任务!$N$2:$N$109,N12)=1,COUNTIFS($A$2:$A$109,A12)=1),"匹配","缺范围或重复") -> 匹配 | T12: 保留首批内容结论，不代表产品齐备 | U12: =E12 -> 0 | V12: 沿用D1/B2已验收结论 | W12: 沿用D1/B2结论，不新增推断 | X12: 未认定齐备 | Y12: 未由本次更新确认 | Z12: D1/B2冻结验收历史 | AA12: 新增列仅分层说明；原有任务结论与来源不覆盖。 | AB12: MY-SUN-031
A13: D1-MY-005 | B13: 马来西亚 | C13: 已复核 | D13: 已逐页审读26页马来文。确认MRTTFB20及2020-07-01批单；主要给付及费用条文在件。MRTT002未见、性质待核；当前采用未证。 | E13: 0 | F13: 1 | G13: 0 | H13: 0 | I13: 通过 | J13: 原件SHA、物理页与逐页文字/视觉证据核对通过；现存页全文核验+1（合计5份114页），合同完整性仍待核、合同完整未确认、严格通过增量0；不要求真实个人专属附表。 | K13: 46321 | L13: 核实精确公开采用证据及附表性质，不索取真实客户私人资料。 | M13: =IF(S13<>"匹配","缺范围任务",IF(I13="通过",IF(AND(J13<>"",ISNUMBER(K13),K13>=DATE(2026,10,26)),"已验收","缺证据或日期"),IF(I13="","缺状态","待复核"))) -> 已验收 | N13: D1 | O13: Sun Life Malaysia Takaful Berhad | P13: 26 | Q13: 0 | R13: 0 | S13: =IF(AND(A13<>"",N13<>"",COUNTIFS(首批固定任务!$A$2:$A$109,A13,首批固定任务!$N$2:$N$109,N13)=1,COUNTIFS($A$2:$A$109,A13)=1),"匹配","缺范围或重复") -> 匹配 | T13: 保留首批内容结论，不代表产品齐备 | U13: =E13 -> 0 | V13: 沿用D1/B2已验收结论 | W13: 沿用D1/B2结论，不新增推断 | X13: 未认定齐备 | Y13: 未由本次更新确认 | Z13: D1/B2冻结验收历史 | AA13: 新增列仅分层说明；原有任务结论与来源不覆盖。 | AB13: MY-SUN-077
... A24: B2-KH-002 | B24: 柬埔寨 | C24: 证据已复核 | D24: 18页现存全文通过；p6暂停恢复与p10终止、p4-5 >2小时与p12 >=2小时、p8购单条件与当前FAQ、p18诉期措辞冲突未解决。仍待核验/严格新增0；理赔表是服务包缺件非主文核心缺件。 | E24: 0 | F24: 1 | G24: 0 | H24: 0 | I24: 通过 | J24: 现存18页逐页文本与视觉证据已独立验收。 18页现存全文通过；p6暂停恢复与p10终止、p4-5 >2小时与p12 >=2小时、p8购单条件与当前FAQ、p18诉期措辞冲突未解决。仍待核验/严格新增0；理赔表是服务包缺件非主文核心缺件。 | K24: 46321 | L24: 依准确引用页核实附表性质、采用关系及条文差异。未解决前保持待核验，不计产品齐备。 | M24: =IF(S24<>"匹配","缺范围任务",IF(I24="通过",IF(AND(J24<>"",ISNUMBER(K24),K24>=DATE(2026,10,26)),"已验收","缺证据或日期"),IF(I24="","缺状态","待复核"))) -> 已验收 | N24: B2 | O24: Forte Insurance (Cambodia) PLC. | P24: 18 | Q24: 1 | R24: 0 | S24: =IF(AND(A24<>"",N24<>"",COUNTIFS(首批固定任务!$A$2:$A$109,A24,首批固定任务!$N$2:$N$109,N24)=1,COUNTIFS($A$2:$A$109,A24)=1),"匹配","缺范围或重复") -> 匹配 | T24: 现存页全文已审，合同问题仍待核验 | U24: =E24 -> 0 | V24: 沿用D1/B2已验收结论 | W24: 沿用D1/B2结论，不新增推断 | X24: 未认定齐备 | Y24: 未由本次更新确认 | Z24: D1/B2冻结验收历史 | AA24: 新增列仅分层说明；原有任务结论与来源不覆盖。 | AB24: KH-tuneprotect-current
A25: B3-MY-001 | B25: 马来西亚 | C25: 证据已复核 | D25: 现存34页全文审读已验收；具名主条款角色已核，附表／版本／语言或关联材料问题仍待核。 | E25: 0 | F25: 1 | G25: 0 | H25: 0 | I25: 通过 | J25: B3独立QA · B3-MY-001；34物理页现存文件全文证据。 | K25: 46321 | L25: 仅按已记录引用页和问题定点核证；未解除前不计严格或当前合同包齐备，不索取真实客户资料。 | M25: =IF(S25<>"匹配","缺范围任务",IF(I25="通过",IF(AND(J25<>"",ISNUMBER(K25),K25>=DATE(2026,10,26)),"已验收","缺证据或日期"),IF(I25="","缺状态","待复核"))) -> 已验收 | N25: B3 | O25: Sun Life Malaysia Assurance Berhad | P25: 34 | Q25: 1 | R25: 0 | S25: =IF(AND(A25<>"",N25<>"",COUNTIFS(首批固定任务!$A$2:$A$109,A25,首批固定任务!$N$2:$N$109,N25)=1,COUNTIFS($A$2:$A$109,A25)=1),"匹配","缺范围或重复") -> 匹配 | T25: 现存页全文已审，合同／适用仍待核 | U25: 0 | V25: 具名主合同材料；仍待核验 | W25: 既存具名主文材料，当前适用未核 | X25: 未确认齐备 | Y25: 未核定（不等于否定） | Z25: 既存原件／既有验收事实；非本批重新下载 | AA25: 全文仅指该SHA现存全部页面；不代表当前标准合同包齐全。 | AB25: MY-SUN-006
A26: B3-MY-002 | B26: 马来西亚 | C26: 证据已复核 | D26: 现存48页全文审读已验收；具名主条款角色已核，附表／版本／语言或关联材料问题仍待核。 | E26: 0 | F26: 1 | G26: 0 | H26: 0 | I26: 通过 | J26: B3独立QA · B3-MY-002；48物理页现存文件全文证据。 | K26: 46321 | L26: 仅按已记录引用页和问题定点核证；未解除前不计严格或当前合同包齐备，不索取真实客户资料。 | M26: =IF(S26<>"匹配","缺范围任务",IF(I26="通过",IF(AND(J26<>"",ISNUMBER(K26),K26>=DATE(2026,10,26)),"已验收","缺证据或日期"),IF(I26="","缺状态","待复核"))) -> 已验收 | N26: B3 | O26: Sun Life Malaysia Assurance Berhad | P26: 48 | Q26: 1 | R26: 0 | S26: =IF(AND(A26<>"",N26<>"",COUNTIFS(首批固定任务!$A$2:$A$109,A26,首批固定任务!$N$2:$N$109,N26)=1,COUNTIFS($A$2:$A$109,A26)=1),"匹配","缺范围或重复") -> 匹配 | T26: 现存页全文已审，合同／适用仍待核 | U26: 0 | V26: 具名主合同材料；仍待核验 | W26: 既存具名主文材料，当前适用未核 | X26: 未确认齐备 | Y26: 未核定（不等于否定） | Z26: 既存原件／既有验收事实；非本批重新下载 | AA26: 全文仅指该SHA现存全部页面；不代表当前标准合同包齐全。 | AB26: MY-SUN-019
A27: B3-MY-003 | B27: 马来西亚 | C27: 证据已复核 | D27: 现存23页全文审读已验收；具名主条款角色已核，附表／版本／语言或关联材料问题仍待核。 | E27: 0 | F27: 1 | G27: 0 | H27: 0 | I27: 通过 | J27: B3独立QA · B3-MY-003；23物理页现存文件全文证据。 | K27: 46321 | L27: 仅按已记录引用页和问题定点核证；未解除前不计严格或当前合同包齐备，不索取真实客户资料。 | M27: =IF(S27<>"匹配","缺范围任务",IF(I27="通过",IF(AND(J27<>"",ISNUMBER(K27),K27>=DATE(2026,10,26)),"已验收","缺证据或日期"),IF(I27="","缺状态","待复核"))) -> 已验收 | N27: B3 | O27: Sun Life Malaysia Takaful Berhad | P27: 23 | Q27: 1 | R27: 0 | S27: =IF(AND(A27<>"",N27<>"",COUNTIFS(首批固定任务!$A$2:$A$109,A27,首批固定任务!$N$2:$N$109,N27)=1,COUNTIFS($A$2:$A$109,A27)=1),"匹配","缺范围或重复") -> 匹配 | T27: 现存页全文已审，合同／适用仍待核 | U27: 0 | V27: 具名主合同材料；仍待核验 | W27: 既存具名主文材料，当前适用未核 | X27: 未确认齐备 | Y27: 未核定（不等于否定） | Z27: 既存原件／既有验收事实；非本批重新下载 | AA27: 全文仅指该SHA现存全部页面；不代表当前标准合同包齐全。 | AB27: MY-SUN-043
A28: B3-MY-004 | B28: 马来西亚 | C28: 证据已复核 | D28: 现存41页全文审读已验收；具名主条款角色已核，附表／版本／语言或关联材料问题仍待核。 | E28: 0 | F28: 1 | G28: 0 | H28: 0 | I28: 通过 | J28: B3独立QA · B3-MY-004；41物理页现存文件全文证据。 | K28: 46321 | L28: 仅按已记录引用页和问题定点核证；未解除前不计严格或当前合同包齐备，不索取真实客户资料。 | M28: =IF(S28<>"匹配","缺范围任务",IF(I28="通过",IF(AND(J28<>"",ISNUMBER(K28),K28>=DATE(2026,10,26)),"已验收","缺证据或日期"),IF(I28="","缺状态","待复核"))) -> 已验收 | N28: B3 | O28: Sun Life Malaysia Takaful Berhad | P28: 41 | Q28: 1 | R28: 0 | S28: =IF(AND(A28<>"",N28<>"",COUNTIFS(首批固定任务!$A$2:$A$109,A28,首批固定任务!$N$2:$N$109,N28)=1,COUNTIFS($A$2:$A$109,A28)=1),"匹配","缺范围或重复") -> 匹配 | T28: 现存页全文已审，合同／适用仍待核 | U28: 0 | V28: 具名主合同材料；仍待核验 | W28: 既存具名主文材料，当前适用未核 | X28: 未确认齐备 | Y28: 未核定（不等于否定） | Z28: 既存原件／既有验收事实；非本批重新下载 | AA28: 全文仅指该SHA现存全部页面；不代表当前标准合同包齐全。 | AB28: MY-SUN-080
A29: B3-MY-005 | B29: 马来西亚 | C29: 证据已复核 | D29: 现存38页全文审读已验收；具名主条款角色已核，附表／版本／语言或关联材料问题仍待核。 | E29: 0 | F29: 1 | G29: 0 | H29: 0 | I29: 通过 | J29: B3独立QA · B3-MY-005；38物理页现存文件全文证据。 | K29: 46321 | L29: 仅按已记录引用页和问题定点核证；未解除前不计严格或当前合同包齐备，不索取真实客户资料。 | M29: =IF(S29<>"匹配","缺范围任务",IF(I29="通过",IF(AND(J29<>"",ISNUMBER(K29),K29>=DATE(2026,10,26)),"已验收","缺证据或日期"),IF(I29="","缺状态","待复核"))) -> 已验收 | N29: B3 | O29: Sun Life Malaysia Takaful Berhad | P29: 38 | Q29: 1 | R29: 0 | S29: =IF(AND(A29<>"",N29<>"",COUNTIFS(首批固定任务!$A$2:$A$109,A29,首批固定任务!$N$2:$N$109,N29)=1,COUNTIFS($A$2:$A$109,A29)=1),"匹配","缺范围或重复") -> 匹配 | T29: 现存页全文已审，合同／适用仍待核 | U29: 0 | V29: 具名主合同材料；仍待核验 | W29: 既存具名主文材料，当前适用未核 | X29: 未确认齐备 | Y29: 未核定（不等于否定） | Z29: 既存原件／既有验收事实；非本批重新下载 | AA29: 全文仅指该SHA现存全部页面；不代表当前标准合同包齐全。 | AB29: MY-SUN-097
A30: B3-HK-001 | B30: 香港 | C30: 证据已复核 | D30: 限定已记录公开路线证据已验收；未取得确切目标主文，缺口保留。 | E30: 0 | F30: 0 | G30: 0 | H30: 0 | I30: 通过 | J30: B3独立QA · B3-HK-001；限定公开路线证据。 | K30: 46321 | L30: 有新的准确公开主文入口或明确索取授权时再继续；不重复负面路线、不猜隐藏链接。 | M30: =IF(S30<>"匹配","缺范围任务",IF(I30="通过",IF(AND(J30<>"",ISNUMBER(K30),K30>=DATE(2026,10,26)),"已验收","缺证据或日期"),IF(I30="","缺状态","待复核"))) -> 已验收 | N30: B3 | O30: HSBC Life | P30: 0 | Q30: 0 | R30: 0 | S30: =IF(AND(A30<>"",N30<>"",COUNTIFS(首批固定任务!$A$2:$A$109,A30,首批固定任务!$N$2:$N$109,N30)=1,COUNTIFS($A$2:$A$109,A30)=1),"匹配","缺范围或重复") -> 匹配 | T30: 限定路线完成，主文仍缺 | U30: 0 | V30: 产品页／支持资料，不是主文 | W30: 未取得目标主文 | X30: 未确认齐备 | Y30: 未核定（不等于否定） | Z30: 保存的官方公开响应：HTTP 200 | AA30: 只覆盖保存的响应或摘录；不是全网无主文、穷尽路线或当前在售证明。 | AB30: hsbc-goal-access-universal-education
A31: B3-HK-002 | B31: 香港 | C31: 证据已复核 | D31: 限定已记录公开路线证据已验收；未取得确切目标主文，缺口保留。 | E31: 0 | F31: 0 | G31: 0 | H31: 0 | I31: 通过 | J31: B3独立QA · B3-HK-002；限定公开路线证据。 | K31: 46321 | L31: 有新的准确公开主文入口或明确索取授权时再继续；不重复负面路线、不猜隐藏链接。 | M31: =IF(S31<>"匹配","缺范围任务",IF(I31="通过",IF(AND(J31<>"",ISNUMBER(K31),K31>=DATE(2026,10,26)),"已验收","缺证据或日期"),IF(I31="","缺状态","待复核"))) -> 已验收 | N31: B3 | O31: Hang Seng Insurance | P31: 0 | Q31: 0 | R31: 0 | S31: =IF(AND(A31<>"",N31<>"",COUNTIFS(首批固定任务!$A$2:$A$109,A31,首批固定任务!$N$2:$N$109,N31)=1,COUNTIFS($A$2:$A$109,A31)=1),"匹配","缺范围或重复") -> 匹配 | T31: 限定路线完成，主文仍缺 | U31: 0 | V31: 产品页／支持资料，不是主文 | W31: 未取得目标主文 | X31: 未确认齐备 | Y31: 未核定（不等于否定） | Z31: 保存的官方公开响应：HTTP 200 | AA31: 只覆盖保存的响应或摘录；不是全网无主文、穷尽路线或当前在售证明。 | AB31: hangseng-legend-power-supreme
A32: B3-VN-001 | B32: 越南 | C32: 证据已复核 | D32: 历史精确材料关联2项已验收；当前版本采用仍待核。不新增全文或主文。 | E32: 0 | F32: 0 | G32: 0 | H32: 0 | I32: 通过 | J32: B3独立QA · B3-VN-001；精确历史材料关系证据。 | K32: 46321 | L32: 仅按已记录引用页和问题定点核证；未解除前不计严格或当前合同包齐备，不索取真实客户资料。 | M32: =IF(S32<>"匹配","缺范围任务",IF(I32="通过",IF(AND(J32<>"",ISNUMBER(K32),K32>=DATE(2026,10,26)),"已验收","缺证据或日期"),IF(I32="","缺状态","待复核"))) -> 已验收 | N32: B3 | O32: Công ty TNHH Manulife (Việt Nam) | P32: 0 | Q32: 0 | R32: 0 | S32: =IF(AND(A32<>"",N32<>"",COUNTIFS(首批固定任务!$A$2:$A$109,A32,首批固定任务!$N$2:$N$109,N32)=1,COUNTIFS($A$2:$A$109,A32)=1),"匹配","缺范围或重复") -> 匹配 | T32: 身份／关系／角色已核，不是产品闭合 | U32: 0 | V32: 仅历史材料关系核验 | W32: 当前目标版本采用未核 | X32: 未确认齐备 | Y32: 未核定（不等于否定） | Z32: 既存原件／既有验收事实；非本批重新下载 | AA32: 关系证据不等于全文；不合并资料组或产品。 | AB32: VN-539a4a42cb94
A33: B3-VN-002 | B33: 越南 | C33: 证据已复核 | D33: 历史精确材料关联2项已验收；当前版本采用仍待核。纠正附约被当主合同的角色，主文净减1。 | E33: 0 | F33: 0 | G33: 0 | H33: 0 | I33: 通过 | J33: B3独立QA · B3-VN-002；精确历史材料关系证据。 | K33: 46321 | L33: 仅按已记录引用页和问题定点核证；未解除前不计严格或当前合同包齐备，不索取真实客户资料。 | M33: =IF(S33<>"匹配","缺范围任务",IF(I33="通过",IF(AND(J33<>"",ISNUMBER(K33),K33>=DATE(2026,10,26)),"已验收","缺证据或日期"),IF(I33="","缺状态","待复核"))) -> 已验收 | N33: B3 | O33: Công ty TNHH Manulife (Việt Nam) | P33: 0 | Q33: -1 | R33: 0 | S33: =IF(AND(A33<>"",N33<>"",COUNTIFS(首批固定任务!$A$2:$A$109,A33,首批固定任务!$N$2:$N$109,N33)=1,COUNTIFS($A$2:$A$109,A33)=1),"匹配","缺范围或重复") -> 匹配 | T33: 身份／关系／角色已核，不是产品闭合 | U33: 0 | V33: 附约／补充条款，不是独立主合同 | W33: 当前目标版本采用未核 | X33: 未确认齐备 | Y33: 未核定（不等于否定） | Z33: 既存原件／既有验收事实；非本批重新下载 | AA33: 关系证据不等于全文；不合并资料组或产品。 | AB33: VN-32f604533d33
A34: B3-KH-001 | B34: 柬埔寨 | C34: 证据已复核 | D34: 仅第13–25页英文部分共13物理页已审，12页高棉语法律语义待核；整份保持部分核验。 | E34: 0 | F34: 0 | G34: 0 | H34: 0 | I34: 通过 | J34: B3独立QA · B3-KH-001；13页英文证据；高棉语未审。 | K34: 46321 | L34: 需要可靠高棉语审读并核双语一致及版本；未解除前保持部分核验。 | M34: =IF(S34<>"匹配","缺范围任务",IF(I34="通过",IF(AND(J34<>"",ISNUMBER(K34),K34>=DATE(2026,10,26)),"已验收","缺证据或日期"),IF(I34="","缺状态","待复核"))) -> 已验收 | N34: B3 | O34: Forte Insurance (Cambodia) Plc. | P34: 0 | Q34: 0 | R34: 1 | S34: =IF(AND(A34<>"",N34<>"",COUNTIFS(首批固定任务!$A$2:$A$109,A34,首批固定任务!$N$2:$N$109,N34)=1,COUNTIFS($A$2:$A$109,A34)=1),"匹配","缺范围或重复") -> 匹配 | T34: 部分审读，语言依赖未解 | U34: 0 | V34: 主文候选，当前采用未核 | W34: 有既存候选，产品主文仍未严格确立 | X34: 未确认齐备 | Y34: 未核定（不等于否定） | Z34: 既存原件／既有验收事实；非本批重新下载 | AA34: 仅英文部分，不称整份全文；语言优先关系未定。 | AB34: KH-forte-travel-search
A35: B4-MY-001 | B35: 马来西亚 | C35: 证据已复核 | D35: 25页现存英文主合同全文已审；具名GTTPW合同及附表已核，目录活动名不证明当前采用，条文关系仍待核。 | E35: 0 | F35: 1 | G35: 0 | H35: 0 | I35: 通过 | J35: B4独立QA · B4-MY-001；25物理页现存文件全文证据。 | K35: 46321 | L35: 仅按已记录引用页和问题定点核证；未解除前不计严格或当前合同包齐备，不索取真实客户资料。 | M35: =IF(S35<>"匹配","缺范围任务",IF(I35="通过",IF(AND(J35<>"",ISNUMBER(K35),K35>=DATE(2026,10,26)),"已验收","缺证据或日期"),IF(I35="","缺状态","待复核"))) -> 已验收 | N35: B4 | O35: Sun Life Malaysia Takaful Berhad | P35: 25 | Q35: 1 | R35: 0 | S35: =IF(AND(A35<>"",N35<>"",COUNTIFS(首批固定任务!$A$2:$A$109,A35,首批固定任务!$N$2:$N$109,N35)=1,COUNTIFS($A$2:$A$109,A35)=1),"匹配","缺范围或重复") -> 匹配 | T35: 现存页全文已审，合同／适用仍待核 | U35: 0 | V35: 文件主合同角色已核，仍待核验 | W35: 有既存条款材料，当前产品采用未核 | X35: 未确认齐备 | Y35: 未核定（不等于否定） | Z35: 既存原件／既有验收事实；非本批重新下载 | AA35: 仅现存页面与文件角色；目录活动名与正文具名采用分别判断。 | AB35: MY-SUN-024
A36: B4-MY-002 | B36: 马来西亚 | C36: 证据已复核 | D36: 27页现存英文主合同全文已审；引用附表未附，CIMB／Salary Account目录标签不替代正文具名身份；仍待核。 | E36: 0 | F36: 1 | G36: 0 | H36: 0 | I36: 通过 | J36: B4独立QA · B4-MY-002；27物理页现存文件全文证据。 | K36: 46321 | L36: 仅按已记录引用页和问题定点核证；未解除前不计严格或当前合同包齐备，不索取真实客户资料。 | M36: =IF(S36<>"匹配","缺范围任务",IF(I36="通过",IF(AND(J36<>"",ISNUMBER(K36),K36>=DATE(2026,10,26)),"已验收","缺证据或日期"),IF(I36="","缺状态","待复核"))) -> 已验收 | N36: B4 | O36: Sun Life Malaysia Takaful Berhad | P36: 27 | Q36: 1 | R36: 0 | S36: =IF(AND(A36<>"",N36<>"",COUNTIFS(首批固定任务!$A$2:$A$109,A36,首批固定任务!$N$2:$N$109,N36)=1,COUNTIFS($A$2:$A$109,A36)=1),"匹配","缺范围或重复") -> 匹配 | T36: 现存页全文已审，合同／适用仍待核 | U36: 0 | V36: 文件主合同角色已核，仍待核验 | W36: 有既存条款材料，当前产品采用未核 | X36: 未确认齐备 | Y36: 未核定（不等于否定） | Z36: 既存原件／既有验收事实；非本批重新下载 | AA36: 仅现存页面与文件角色；目录活动名与正文具名采用分别判断。 | AB36: MY-SUN-032
... A109: B14-HK-002 | B109: 香港 | C109: 证据已复核 | D109: Trinity TripCover条款标签单次只读点击，下载等待超时；无文档URL／PDF。未重试旧404路线。 | E109: 0 | F109: 0 | G109: 0 | H109: 0 | I109: 通过 | J109: B14独立QA · B14-HK-002；限定路线证据，原件／全文增量0。 | K109: 46321 | L109: 保留当前停止点；仅新确切公开证据或明确授权可重开，不重复负面探测或猜测路径。 | M109: =IF(S109<>"匹配","缺范围任务",IF(I109="通过",IF(AND(J109<>"",ISNUMBER(K109),K109>=DATE(2026,10,26)),"已验收","缺证据或日期"),IF(I109="","缺状态","待复核"))) -> 已验收 | N109: B14 | O109: Trinity General Insurance Company Limited | P109: 0 | Q109: 0 | R109: 0 | S109: =IF(AND(A109<>"",N109<>"",COUNTIFS(首批固定任务!$A$2:$A$109,A109,首批固定任务!$N$2:$N$109,N109)=1,COUNTIFS($A$2:$A$109,A109)=1),"匹配","缺范围或重复") -> 匹配 | T109: 限定路线完成；目标主文未取得 | U109: 0 | V109: 公开路线／线索，无已取得主文 | W109: 未确立目标产品主文可得 | X109: 未确认齐备 | Y109: 未核定（不等于否定） | Z109: 普通浏览器只读点击的保存元数据摘录；HTTP未知 | AA109: 保存的是工具元数据摘录，不是完整原始轨迹。时间为动作前后／等待完成上界；截图未保存供独立视觉复核。 | AB109: LABEL:9464feb717becffdb641ebbb

Sheet 首批固定任务
A1: 任务ID | B1: 地区 | C1: 保司 | D1: 产品／组件 | E1: 原始产品ID | F1: 任务单位 | G1: 交付要求 | H1: 期初状态 | I1: 期初下一步 | J1: 来源ID | K1: 期初验收证据 | L1: 期初完成日 | M1: 期初验收判定 | N1: 批次
A2: D1-HK-001 | B2: 香港 | C2: AIA 友邦香港 | D2: 「簡愛‧延續」儲蓄保險計劃5 | E2: aia-simply-love-encore-5 | F2: 产品路线核验 | G2: 保留准确产品身份、页面/附件URL、访问时间与结果；主文取得与路线处理完成分开；无正文仍可交付明确缺口，不算产品齐备 | H2: 已冻结 | I2: 按该产品官方页及可见附件逐项检查；有明确同产品销售来源才进入第二层；取得匹配主文即转核验，否则记录缺件与停止原因 | J2: SRC-D1-HK-001 | M2: =IF(H2="已验收",IF(AND(K2<>"",ISNUMBER(L2)),"已验收","缺证据或日期"),IF(H2="","缺状态","未验收")) -> 未验收 | N2: D1
A3: D1-HK-002 | B3: 香港 | C3: Manulife 宏利香港 | D3: 宏瑞終身即期年金保險計劃 | E3: manulife-goldenstart | F3: 产品路线核验 | G3: 保留准确产品身份、页面/附件URL、访问时间与结果；主文取得与路线处理完成分开；无正文仍可交付明确缺口，不算产品齐备 | H3: 已冻结 | I3: 按该产品官方页及可见附件逐项检查；有明确同产品销售来源才进入第二层；取得匹配主文即转核验，否则记录缺件与停止原因 | J3: SRC-D1-HK-002 | M3: =IF(H3="已验收",IF(AND(K3<>"",ISNUMBER(L3)),"已验收","缺证据或日期"),IF(H3="","缺状态","未验收")) -> 未验收 | N3: D1
A4: D1-HK-003 | B4: 香港 | C4: Prudential 保诚香港 | D4: Prime Horizon Insurance Plan | E4: prudential-prime-horizon-insurance-plan | F4: 产品路线核验 | G4: 保留准确产品身份、页面/附件URL、访问时间与结果；主文取得与路线处理完成分开；无正文仍可交付明确缺口，不算产品齐备 | H4: 已冻结 | I4: 按该产品官方页及可见附件逐项检查；有明确同产品销售来源才进入第二层；取得匹配主文即转核验，否则记录缺件与停止原因 | J4: SRC-D1-HK-003 | M4: =IF(H4="已验收",IF(AND(K4<>"",ISNUMBER(L4)),"已验收","缺证据或日期"),IF(H4="","缺状态","未验收")) -> 未验收 | N4: D1
A5: D1-HK-004 | B5: 香港 | C5: Sun Life 永明香港 | D5: 永譽傳承儲蓄計劃 | E5: sunlife-royalfortune | F5: 产品路线核验 | G5: 保留准确产品身份、页面/附件URL、访问时间与结果；主文取得与路线处理完成分开；无正文仍可交付明确缺口，不算产品齐备 | H5: 已冻结 | I5: 按该产品官方页及可见附件逐项检查；有明确同产品销售来源才进入第二层；取得匹配主文即转核验，否则记录缺件与停止原因 | J5: SRC-D1-HK-004 | M5: =IF(H5="已验收",IF(AND(K5<>"",ISNUMBER(L5)),"已验收","缺证据或日期"),IF(H5="","缺状态","未验收")) -> 未验收 | N5: D1
A6: D1-SG-001 | B6: 新加坡 | C6: Allied World Assurance Company, Ltd (Singapore Branch) | D6: Travel Protector 2024基准主文的现行COVID-19扩展/批单 | E6: SG-F-c279cfe77714176e | F6: 产品组件核验 | G6: 取得准确组件且有采用依据，或交付确定缺件与已查路线；保留已核26页主文，不升级整套齐备 | H6: 已冻结 | I6: 仅围绕当前官方1026宣传册40–48项COVID保障寻找明确采用的扩展或批单；比对2024主文第14页COVID除外及计划差异 | J6: SRC-D1-SG-001 | M6: =IF(H6="已验收",IF(AND(K6<>"",ISNUMBER(L6)),"已验收","缺证据或日期"),IF(H6="","缺状态","未验收")) -> 未验收 | N6: D1
A7: D1-SG-002 | B7: 新加坡 | C7: Allied World Assurance Company, Ltd (Singapore Branch) | D7: Home Protector 360 06/20版的现行采用与Basic隔离 | E7: SG-F-14656bec56df8d86 | F7: 产品版本核验 | G7: 提供准确版次采用证据或保持未证；360与Basic分开；不把宣传册目录2018/09当版本 | H7: 已冻结 | I7: 核0326官方宣传册/产品页是否明确采用06/20主文或有替代版；Basic单列缺口，不把360套给Basic | J7: SRC-D1-SG-002 | M7: =IF(H7="已验收",IF(AND(K7<>"",ISNUMBER(L7)),"已验收","缺证据或日期"),IF(H7="","缺状态","未验收")) -> 未验收 | N7: D1
A8: D1-SG-003 | B8: 新加坡 | C8: Utmost Worldwide Limited (Singapore Branch) | D8: FOCUS UWWS PR00030 09/25页序与完整性 | E8: SG-4330cfac28a50f2e | F8: 文档核验 | G8: 逐页页码/内容连续性记录及缺页判定依据；未能消除疑点则保留未完整，不升级主文缺口或新增文件 | H8: 已冻结 | I8: 仅核现有21物理页与正文页脚24页标注的关系；对照目录/段落/末页和官方同版说明，不因物理页差直接断言缺3页 | J8: SRC-D1-SG-003 | M8: =IF(H8="已验收",IF(AND(K8<>"",ISNUMBER(L8)),"已验收","缺证据或日期"),IF(H8="","缺状态","未验收")) -> 未验收 | N8: D1
A9: D1-MY-001 | B9: 马来西亚 | C9: Sun Life Malaysia Assurance Berhad | D9: Cancer Plan Master Policy | E9: MY-SUN-005 | F9: 文档核验 | G9: 逐页完成清单+角色与主体/渠道结论+版次或未知标记+缺件矩阵；扫描/多语言无法可靠判断时维持待审，不因文本提取或Master文件名升级 | H9: 已冻结 | I9: 校对全部页码及正文可读性；确定法律主体、团体/个人与渠道、正文版次及角色；列引用证书/附约依赖和疑点页码；按文档记录实测时间 | J9: SRC-D1-MY-001 | M9: =IF(H9="已验收",IF(AND(K9<>"",ISNUMBER(L9)),"已验收","缺证据或日期"),IF(H9="","缺状态","未验收")) -> 未验收 | N9: D1
A10: D1-MY-002 | B10: 马来西亚 | C10: Sun Life Malaysia Assurance Berhad | D10: Biz Shield Master Policy | E10: MY-SUN-002 | F10: 文档核验 | G10: 逐页完成清单+角色与主体/渠道结论+版次或未知标记+缺件矩阵；扫描/多语言无法可靠判断时维持待审，不因文本提取或Master文件名升级 | H10: 已冻结 | I10: 校对全部页码及正文可读性；确定法律主体、团体/个人与渠道、正文版次及角色；列引用证书/附约依赖和疑点页码；按文档记录实测时间 | J10: SRC-D1-MY-002 | M10: =IF(H10="已验收",IF(AND(K10<>"",ISNUMBER(L10)),"已验收","缺证据或日期"),IF(H10="","缺状态","未验收")) -> 未验收 | N10: D1
A11: D1-MY-003 | B11: 马来西亚 | C11: Sun Life Malaysia Takaful Berhad | D11: Group Term Takaful (GTT ADB) Master Contract - ILP Protection Campaign | E11: MY-SUN-029 | F11: 文档核验 | G11: 逐页完成清单+角色与主体/渠道结论+版次或未知标记+缺件矩阵；扫描/多语言无法可靠判断时维持待审，不因文本提取或Master文件名升级 | H11: 已冻结 | I11: 校对全部页码及正文可读性；确定法律主体、团体/个人与渠道、正文版次及角色；列引用证书/附约依赖和疑点页码；按文档记录实测时间 | J11: SRC-D1-MY-003 | M11: =IF(H11="已验收",IF(AND(K11<>"",ISNUMBER(L11)),"已验收","缺证据或日期"),IF(H11="","缺状态","未验收")) -> 未验收 | N11: D1
A12: D1-MY-004 | B12: 马来西亚 | C12: Sun Life Malaysia Takaful Berhad | D12: Group Term Takaful (GTT) Master Contract - Protection with Purpose roadshow Campaign | E12: MY-SUN-031 | F12: 文档核验 | G12: 逐页完成清单+角色与主体/渠道结论+版次或未知标记+缺件矩阵；扫描/多语言无法可靠判断时维持待审，不因文本提取或Master文件名升级 | H12: 已冻结 | I12: 校对全部页码及正文可读性；确定法律主体、团体/个人与渠道、正文版次及角色；列引用证书/附约依赖和疑点页码；按文档记录实测时间 | J12: SRC-D1-MY-004 | M12: =IF(H12="已验收",IF(AND(K12<>"",ISNUMBER(L12)),"已验收","缺证据或日期"),IF(H12="","缺状态","未验收")) -> 未验收 | N12: D1
A13: D1-MY-005 | B13: 马来西亚 | C13: Sun Life Malaysia Takaful Berhad | D13: Mortgage Reducing Term Takaful with Funeral Benefit 2020 Master Contract | E13: MY-SUN-077 | F13: 文档核验 | G13: 逐页完成清单+角色与主体/渠道结论+版次或未知标记+缺件矩阵；扫描/多语言无法可靠判断时维持待审，不因文本提取或Master文件名升级 | H13: 已冻结 | I13: 校对全部页码及正文可读性；确定法律主体、团体/个人与渠道、正文版次及角色；列引用证书/附约依赖和疑点页码；按文档记录实测时间 | J13: SRC-D1-MY-005 | M13: =IF(H13="已验收",IF(AND(K13<>"",ISNUMBER(L13)),"已验收","缺证据或日期"),IF(H13="","缺状态","未验收")) -> 未验收 | N13: D1
... A109: B14-HK-002 | B109: 香港 | C109: Trinity General Insurance Company Limited | D109: Trinity TripCover policy wording control | E109: LABEL:9464feb717becffdb641ebbb | F109: 限定只读标签探测 | G109: 仅按冻结范围与独立QA验收，不自动升级原件、主文、严格或产品闭合。 | H109: 已冻结 | I109: 限定已记录公开路线；记录停止原因，不猜路径或绕过限制。 | J109: SRC-B14-HK-002 | M109: =IF(H109="已验收",IF(AND(K109<>"",ISNUMBER(L109)),"已验收","缺证据或日期"),IF(H109="","缺状态","未验收")) -> 未验收 | N109: B14

Sheet 12地区基线
A1: 地区码 | B1: 地区 | C1: 基线状态 | D1: 正式文件 | E1: 已全文审阅 | F1: 严格通过 | G1: 隔离文件 | H1: 范围家族数 | I1: 已识别主合同 | J1: 待补主合同 | K1: 本批重点 | L1: 最近检查 | M1: 来源索引 | N1: 统计说明
A2: HK | B2: 香港 | C2: 已有文件，继续核验 | D2: 2326 | E2: 1132 | F2: 146 | G2: 26 | H2: 203 | I2: 36 | J2: 167 | K2: 先核未逐项检查缺口；分开未检查、未取得、受限和待授权。 | L2: 46320 | M2: 香港：52 条来源 | N2: 仅限定储蓄203族；不是全市场在售或独立产品分母。。储蓄限定203族中167缺主文；上一轮55族仅逐查16族，另112族仅逐查15族及7家公司代表路线，未逐项全查。
A3: SG | B3: 新加坡 | C3: 已有文件，继续核验 | D3: 496 | E3: 420 | F3: 94 | G3: 2 | H3: 144 | I3: 115 | J3: 29 | K3: 先核确切版本和组件依赖；144窄口径与294族投影分开。 | L3: 46320 | M3: 新加坡：25 条来源 | N3: 仅历史窄范围144族；不得与294族归一化投影或全市场分母混用。。窄口径144族中29缺主文；Travel Protector仍缺适用组件，Home360为2020版，现行适用未证，不得套用于Basic。
A4: MY | B4: 马来西亚 | C4: 已有文件，继续核验 | D4: 597 | E4: 241 | F4: 43 | G4: 0 | K4: 暂停泛扩下载，先验收已取得Master候选。 | L4: 46320 | M4: 马来西亚：7 条来源 | N4: 全市场独立产品分母未知；文件数不能作产品数或覆盖率。。Sun Life本轮124份候选含103份Master及21份certificate，均待全文；法律主体、团体/个人和银行渠道不能混。
A5: VN | B5: 越南 | C5: 已有文件，继续核验 | D5: 572 | E5: 171 | F5: 29 | G5: 1 | K5: 校正身份和关系，BHV Appendix 01等具体缺件单列。 | L5: 46320 | M5: 越南：24 条来源 | N5: 全市场独立产品分母未知；文件数不能作产品数或覆盖率。。24条关系修复涉及23个来源组；21项多变体关系待审，部分所谓缺主文项实为附约。
A6: ID | B6: 印度尼西亚 | C6: 已有文件，继续核验 | D6: 89 | E6: 20 | F6: 3 | G6: 1 | K6: 核验PSATSI并找具名产品采用证据；受限件不破解。 | L6: 46320 | M6: 印度尼西亚：1 条来源 | N6: 全市场独立产品分母未知；文件数不能作产品数或覆盖率。。MAG PSAPBI已全文但为标准支持件，不能当具名产品主文；PSATSI待核，另有密码受限文件。
A7: TH | B7: 泰国 | C7: 已有文件，继续核验 | D7: 219 | E7: 115 | F7: 59 | G7: 0 | K7: 清理角色、双语及版本关系；不将重复文件计新增。 | L7: 46320 | M7: 泰国：3 条来源 | N7: 全市场独立产品分母未知；文件数不能作产品数或覆盖率。。Roojai新入口多为既有文件；主文、摘要、附加条款及服务协议混杂，部分PDF 403。
A8: PH | B8: 菲律宾 | C8: 已有文件，继续核验 | D8: 53 | E8: 52 | F8: 12 | G8: 1 | K8: 交付疑点页码与必要缺件；历史及不完整页不升strict。 | L8: 46320 | M8: 菲律宾：3 条来源 | N8: 全市场独立产品分母未知；文件数不能作产品数或覆盖率。。FWD KanGuard与KanMend两份现官网样本文已全文，但给付对象或定义有疑点，资料包未齐。
A9: KH | B9: 柬埔寨 | C9: 已有文件，继续核验 | D9: 199 | E9: 42 | F9: 7 | G9: 13 | K9: 先审3份现公开候选及高棉文内容，分别保留历史/采用待核。 | L9: 46320 | M9: 柬埔寨：13 条来源 | N9: 全市场独立产品分母未知；文件数不能作产品数或覆盖率。。本轮6份正文候选待核；3份有现公开直链、1份历史、2份官方托管但现行采用未证。
A10: BN | B10: 文莱 | C10: 已有文件，继续核验 | D10: 33 | E10: 33 | F10: 16 | G10: 0 | K10: 核对身份与关联，区分复用与新增文件。 | L10: 46320 | M10: 文莱：4 条来源 | N10: 全市场独立产品分母未知；文件数不能作产品数或覆盖率。。TAIB同页4条关系修复复用既有原件；National EPP仅见投保书及产品说明。
A11: LA | B11: 老挝 | C11: 已有文件，继续核验 | D11: 40 | E11: 7 | F11: 2 | G11: 7 | K11: 建立共享条款适用矩阵和附录依赖，不用共用文件合并产品。 | L11: 46320 | M11: 老挝：2 条来源 | N11: 全市场独立产品分母未知；文件数不能作产品数或覆盖率。。AGL库主文及附录多为既有文件；多产品共用空白附录，部分入口验证码。
A12: MM | B12: 缅甸 | C12: 已有文件，继续核验 | D12: 86 | E12: 12 | F12: 0 | G12: 0 | K12: 审组件依赖及法律版本；遇验证挑战停止该入口。 | L12: 46320 | M12: 缅甸：9 条来源 | N12: 全市场独立产品分母未知；文件数不能作产品数或覆盖率。。FNI本轮7份仅支持/附加组件且待核；名称含TC亦可能只是brief或summary。
A13: TL | B13: 东帝汶 | C13: 正式库尚无文件 | D13: 0 | E13: 0 | F13: 0 | G13: 0 | K13: 建立本地主体及目录，保留缺口；不以印尼或跨境产品冒充本地覆盖。 | L13: 46320 | M13: 东帝汶：3 条来源 | N13: 正式库尚无东帝汶本地原件；0文件不等于当地无产品，市场产品分母仍未知。。本地正式原件0；可见一般险主体及目录线索，但寿险当前牌照与本地入口未证。

Sheet 保司与来源
A1: 来源ID | B1: 地区 | C1: 保司／机构 | D1: 来源类型 | E1: 来源名称 | F1: 版本／范围 | G1: 最近检查 | H1: 核验状态 | I1: 来源入口 | J1: 文件链接 | K1: 证据边界 | L1: 批次
A2: SRC-HK-6c2c38706b | B2: 香港 | D2: 本地银行销售渠道 | E2: www.dahsing.com | F2: dahsing-sunjoy | G2: 46320 | H2: 页面可访问；所查可见链接未取得匹配主文 | I2: =HYPERLINK("https://www.dahsing.com/en/html/insurance/life_insurance/sunjoy_global_insurance_ii.html","https://www.dahsing.com/en/html/insurance/life_insurance/sunjoy_global_insurance_ii.html") -> https://www.dahsing.com/en/html/insurance/life_insurance/sunjoy_global_insurance_ii.html | K2: 历史本轮记录日期；非今日重访。仅沿冻结的产品/版本处理明确缺件；不重跑已结案路线。 | L2: D1及历史
A3: SRC-HK-4750d4b12c | B3: 香港 | D3: 本地银行销售渠道 | E3: www.dbs.com.hk | F3: dbs-savings | G3: 46320 | H3: 访问失败：HTTP Error 403: Forbidden | I3: =HYPERLINK("https://www.dbs.com.hk/private-banking/insurance/saving-retirement-income/default.page?rd=err","https://www.dbs.com.hk/private-banking/insurance/saving-retirement-income/default.page?rd=err") -> https://www.dbs.com.hk/private-banking/insurance/saving-retirement-income/default.page?rd=err | K3: 历史本轮记录日期；非今日重访。停止该受限入口；仅新授权/新官方入口或版本变化后复查。 | L3: D1及历史
A4: SRC-HK-e87ae103e8 | B4: 香港 | D4: 本地银行销售渠道 | E4: www.sc.com | F4: sc-insurance | G4: 46320 | H4: 页面可访问；所查可见链接未取得匹配主文 | I4: =HYPERLINK("https://www.sc.com/hk/insurance/","https://www.sc.com/hk/insurance/") -> https://www.sc.com/hk/insurance/ | K4: 历史本轮记录日期；非今日重访。仅沿冻结的产品/版本处理明确缺件；不重跑已结案路线。 | L4: D1及历史
A5: SRC-HK-5e1c5fa6df | B5: 香港 | D5: 本地银行销售渠道 | E5: www.sc.com | F5: sc-savings | G5: 46320 | H5: 页面可访问；所查可见链接未取得匹配主文 | I5: =HYPERLINK("https://www.sc.com/hk/insurance/life-insurance/savings-legacy-planning/","https://www.sc.com/hk/insurance/life-insurance/savings-legacy-planning/") -> https://www.sc.com/hk/insurance/life-insurance/savings-legacy-planning/ | K5: 历史本轮记录日期；非今日重访。仅沿冻结的产品/版本处理明确缺件；不重跑已结案路线。 | L5: D1及历史
A6: SRC-HK-af614e1616 | B6: 香港 | C6: AIA（东亚银行销售渠道） | D6: 本地银行销售渠道 | E6: www.hkbea.com | F6: bank-aia-deferred-annuity-plan-2 | G6: 46320 | H6: 页面可访问；所查可见链接未取得匹配主文；页面提示可按需索取 | I6: =HYPERLINK("https://www.hkbea.com/html/en/aia-deferred-annuity-plan-2.html","https://www.hkbea.com/html/en/aia-deferred-annuity-plan-2.html") -> https://www.hkbea.com/html/en/aia-deferred-annuity-plan-2.html | K6: 历史本轮记录日期；非今日重访。仅沿冻结的产品/版本处理明确缺件；不重跑已结案路线。 | L6: D1及历史
A7: SRC-HK-0f749b75df | B7: 香港 | C7: AIA（东亚银行销售渠道） | D7: 本地银行销售渠道 | E7: www.hkbea.com | F7: bea-aia | G7: 46320 | H7: 页面可访问；所查可见链接未取得匹配主文 | I7: =HYPERLINK("https://www.hkbea.com/html/en/bea-aia-partnership.html","https://www.hkbea.com/html/en/bea-aia-partnership.html") -> https://www.hkbea.com/html/en/bea-aia-partnership.html | K7: 历史本轮记录日期；非今日重访。仅沿冻结的产品/版本处理明确缺件；不重跑已结案路线。 | L7: D1及历史
A8: SRC-HK-4658d34b2c | B8: 香港 | C8: AIA（东亚银行销售渠道） | D8: 本地银行销售渠道 | E8: www.hkbea.com | F8: bank-global-power-multi-currency-plan-3 | G8: 46320 | H8: 页面可访问；所查可见链接未取得匹配主文；页面提示可按需索取 | I8: =HYPERLINK("https://www.hkbea.com/html/en/global-power-multi-currency-plan-3.html","https://www.hkbea.com/html/en/global-power-multi-currency-plan-3.html") -> https://www.hkbea.com/html/en/global-power-multi-currency-plan-3.html | K8: 历史本轮记录日期；非今日重访。仅沿冻结的产品/版本处理明确缺件；不重跑已结案路线。 | L8: D1及历史
A9: SRC-HK-cec52af9e6 | B9: 香港 | C9: AIA（东亚银行销售渠道） | D9: 本地银行销售渠道 | E9: www.hkbea.com | F9: bank-globalflexi-savings | G9: 46320 | H9: 页面可访问；所查可见链接未取得匹配主文；页面提示可按需索取 | I9: =HYPERLINK("https://www.hkbea.com/html/en/globalflexi-savings.html","https://www.hkbea.com/html/en/globalflexi-savings.html") -> https://www.hkbea.com/html/en/globalflexi-savings.html | K9: 历史本轮记录日期；非今日重访。仅沿冻结的产品/版本处理明确缺件；不重跑已结案路线。 | L9: D1及历史
A10: SRC-HK-e073e2aece | B10: 香港 | C10: AIA（东亚银行销售渠道） | D10: 本地银行销售渠道 | E10: www.hkbea.com | F10: bank-prosper-life-insurance-plan | G10: 46320 | H10: 页面可访问；所查可见链接未取得匹配主文；页面提示可按需索取 | I10: =HYPERLINK("https://www.hkbea.com/html/en/prosper-life-insurance-plan.html","https://www.hkbea.com/html/en/prosper-life-insurance-plan.html") -> https://www.hkbea.com/html/en/prosper-life-insurance-plan.html | K10: 历史本轮记录日期；非今日重访。仅沿冻结的产品/版本处理明确缺件；不重跑已结案路线。 | L10: D1及历史
A11: SRC-HK-f2ead39462 | B11: 香港 | C11: AIA（东亚银行销售渠道） | D11: 本地银行销售渠道 | E11: www.hkbea.com | F11: bank-wealth-flexi-savings | G11: 46320 | H11: 页面可访问；所查可见链接未取得匹配主文；页面提示可按需索取 | I11: =HYPERLINK("https://www.hkbea.com/html/en/wealth-flexi-savings.html","https://www.hkbea.com/html/en/wealth-flexi-savings.html") -> https://www.hkbea.com/html/en/wealth-flexi-savings.html | K11: 历史本轮记录日期；非今日重访。仅沿冻结的产品/版本处理明确缺件；不重跑已结案路线。 | L11: D1及历史
A12: SRC-HK-a4099bf446 | B12: 香港 | C12: AXA | D12: 保险公司官方 | E12: www.axa.com.hk | F12: 「賞精彩」延期年金計劃 | G12: 46320 | H12: 可见公开页面未取得新增匹配主文；宣传册/优惠/支持件不等于主合同 | I12: =HYPERLINK("https://www.axa.com.hk/zh/downloads/life-and-savings","https://www.axa.com.hk/zh/downloads/life-and-savings") -> https://www.axa.com.hk/zh/downloads/life-and-savings | K12: 历史逐请求检查时间。仅沿冻结的产品/版本处理明确缺件；不重跑已结案路线。 | L12: D1及历史
A13: SRC-HK-35bf5afc81 | B13: 香港 | C13: BOC Life | D13: 保险公司官方 | E13: www.boclife.com.hk | F13: 中銀人壽延期年金計劃（終身） | G13: 46320 | H13: 可见公开页面未取得新增匹配主文；宣传册/优惠/支持件不等于主合同 | I13: =HYPERLINK("https://www.boclife.com.hk/tc/product/boc-life-deferred-annuity-lifetime.html","https://www.boclife.com.hk/tc/product/boc-life-deferred-annuity-lifetime.html") -> https://www.boclife.com.hk/tc/product/boc-life-deferred-annuity-lifetime.html | K13: 历史逐请求检查时间。仅沿冻结的产品/版本处理明确缺件；不重跑已结案路线。 | L13: D1及历史
A14: SRC-HK-13a41ae0a6 | B14: 香港 | C14: BOC Life | D14: 保险公司官方 | E14: www.boclife.com.hk | F14: 鑄富世代環球終身保險計劃 | G14: 46320 | H14: 可见公开页面未取得新增匹配主文；宣传册/优惠/支持件不等于主合同 | I14: =HYPERLINK("https://www.boclife.com.hk/tc/product/eternal-fortune-global-whole-life-insurance-plan.html","https://www.boclife.com.hk/tc/product/eternal-fortune-global-whole-life-insurance-plan.html") -> https://www.boclife.com.hk/tc/product/eternal-fortune-global-whole-life-insurance-plan.html | K14: 历史逐请求检查时间。仅沿冻结的产品/版本处理明确缺件；不重跑已结案路线。 | L14: D1及历史
A15: SRC-HK-5bad78e05e | B15: 香港 | C15: BOC Life | D15: 保险公司官方 | E15: www.boclife.com.hk | F15: 薪火傳承環球終身保險計劃 | G15: 46320 | H15: 可见公开页面未取得新增匹配主文；宣传册/优惠/支持件不等于主合同 | I15: =HYPERLINK("https://www.boclife.com.hk/tc/product/glamorous-glow-global-whole-life-insurance-plan.html","https://www.boclife.com.hk/tc/product/glamorous-glow-global-whole-life-insurance-plan.html") -> https://www.boclife.com.hk/tc/product/glamorous-glow-global-whole-life-insurance-plan.html | K15: 历史逐请求检查时间。仅沿冻结的产品/版本处理明确缺件；不重跑已结案路线。 | L15: D1及历史
A16: SRC-HK-c7c3c03592 | B16: 香港 | C16: BOC Life | D16: 保险公司官方 | E16: www.boclife.com.hk | F16: 月悅出息終身享保險計劃 | G16: 46320 | H16: 可见公开页面未取得新增匹配主文；宣传册/优惠/支持件不等于主合同 | I16: =HYPERLINK("https://www.boclife.com.hk/tc/product/incomejoy-lifelong-insurance-plan.html","https://www.boclife.com.hk/tc/product/incomejoy-lifelong-insurance-plan.html") -> https://www.boclife.com.hk/tc/product/incomejoy-lifelong-insurance-plan.html | K16: 历史逐请求检查时间。仅沿冻结的产品/版本处理明确缺件；不重跑已结案路线。 | L16: D1及历史
A17: SRC-HK-99bdea2859 | B17: 香港 | C17: BOC Life | D17: 保险公司官方 | E17: www.boclife.com.hk | F17: 目標三年保險計劃 | G17: 46320 | H17: 可见公开页面未取得新增匹配主文；宣传册/优惠/支持件不等于主合同 | I17: =HYPERLINK("https://www.boclife.com.hk/tc/product/target3-years-insurance-plan.html","https://www.boclife.com.hk/tc/product/target3-years-insurance-plan.html") -> https://www.boclife.com.hk/tc/product/target3-years-insurance-plan.html | K17: 历史逐请求检查时间。仅沿冻结的产品/版本处理明确缺件；不重跑已结案路线。 | L17: D1及历史
A18: SRC-HK-4910d0077b | B18: 香港 | C18: BOC Life | D18: 保险公司官方 | E18: www.boclife.com.hk | F18: 精選目標五年保險計劃 | G18: 46320 | H18: 可见公开页面未取得新增匹配主文；宣传册/优惠/支持件不等于主合同 | I18: =HYPERLINK("https://www.boclife.com.hk/tc/product/target5-years-plus-insurance-plan.html","https://www.boclife.com.hk/tc/product/target5-years-plus-insurance-plan.html") -> https://www.boclife.com.hk/tc/product/target5-years-plus-insurance-plan.html | K18: 历史逐请求检查时间。仅沿冻结的产品/版本处理明确缺件；不重跑已结案路线。 | L18: D1及历史
A19: SRC-HK-605320de19 | B19: 香港 | C19: CTF Life | D19: 保险公司官方 | E19: www.ctflife.com.hk | F19: 「盛悅」萬用保險保障計劃 | G19: 46320 | H19: 返回验证挑战，未取得真正产品页面；已停止该入口 | I19: =HYPERLINK("https://www.ctflife.com.hk/tc/product/wealth/gorgeous-universal-life-protection-plan","https://www.ctflife.com.hk/tc/product/wealth/gorgeous-universal-life-protection-plan") -> https://www.ctflife.com.hk/tc/product/wealth/gorgeous-universal-life-protection-plan | K19: 历史逐请求检查时间。停止该受限入口；仅新授权/新官方入口或版本变化后复查。 | L19: D1及历史
A20: SRC-HK-ba187b4d0d | B20: 香港 | C20: CTF Life | D20: 保险公司官方 | E20: www.ctflife.com.hk | F20: 「匠心 • 傳承」儲蓄保險計劃 2 (優越版) | G20: 46320 | H20: 返回验证挑战，未取得真正产品页面；已停止该入口 | I20: =HYPERLINK("https://www.ctflife.com.hk/tc/product/wealth/mywealth-savings-insurance-plan-2-prestige","https://www.ctflife.com.hk/tc/product/wealth/mywealth-savings-insurance-plan-2-prestige") -> https://www.ctflife.com.hk/tc/product/wealth/mywealth-savings-insurance-plan-2-prestige | K20: 历史逐请求检查时间。停止该受限入口；仅新授权/新官方入口或版本变化后复查。 | L20: D1及历史
A21: SRC-HK-a29b5bed4b | B21: 香港 | C21: CTF Life | D21: 保险公司官方 | E21: www.ctflife.com.hk | F21: 「飛揚．88」儲蓄保險計劃 | G21: 46320 | H21: 返回验证挑战，未取得真正产品页面；已停止该入口 | I21: =HYPERLINK("https://www.ctflife.com.hk/tc/product/wealth/sky-leap-88-savings-insurance-plan","https://www.ctflife.com.hk/tc/product/wealth/sky-leap-88-savings-insurance-plan") -> https://www.ctflife.com.hk/tc/product/wealth/sky-leap-88-savings-insurance-plan | K21: 历史逐请求检查时间。停止该受限入口；仅新授权/新官方入口或版本变化后复查。 | L21: D1及历史
A22: SRC-HK-266e3e3809 | B22: 香港 | C22: China Life (Overseas) | D22: 保险公司官方 | E22: chinalife.com.hk | F22: Grand Horizon Savings Insurance Plan (Exclusive to Broker Channel) | G22: 46320 | H22: 可见公开页面未取得新增匹配主文；宣传册/优惠/支持件不等于主合同 | I22: =HYPERLINK("https://chinalife.com.hk/products/insurance/grand-horizon-savings-insurance-plan-exclusive-to-broker-channel","https://chinalife.com.hk/products/insurance/grand-horizon-savings-insurance-plan-exclusive-to-broker-channel") -> https://chinalife.com.hk/products/insurance/grand-horizon-savings-insurance-plan-exclusive-to-broker-channel | K22: 历史逐请求检查时间。仅沿冻结的产品/版本处理明确缺件；不重跑已结案路线。 | L22: D1及历史
A23: SRC-HK-68cd7e8e87 | B23: 香港 | C23: China Pacific Life Insurance (H.K.) Company Limited | D23: 保险公司官方 | E23: www.cpiclifehk.com.hk | F23: 世代悅享儲蓄保險計劃3 | G23: 46320 | H23: 可见公开页面未取得新增匹配主文；宣传册/优惠/支持件不等于主合同 | I23: =HYPERLINK("https://www.cpiclifehk.com.hk/ProductIntroduce/ProductDetail?productCode=Everlasting-Joy-3","https://www.cpiclifehk.com.hk/ProductIntroduce/ProductDetail?productCode=Everlasting-Joy-3") -> https://www.cpiclifehk.com.hk/ProductIntroduce/ProductDetail?productCode=Everlasting-Joy-3 | K23: 历史逐请求检查时间。仅沿冻结的产品/版本处理明确缺件；不重跑已结案路线。 | L23: D1及历史
A24: SRC-HK-094918c851 | B24: 香港 | C24: Chubb Life | D24: 保险公司官方 | E24: www.chubb.com | F24: Chubb Future Achiever Savings Plan II | G24: 46320 | H24: 可见公开页面未取得新增匹配主文；宣传册/优惠/支持件不等于主合同 | I24: =HYPERLINK("https://www.chubb.com/hk-en/personal/chubb-future-achiever-savings-plan-2.html","https://www.chubb.com/hk-en/personal/chubb-future-achiever-savings-plan-2.html") -> https://www.chubb.com/hk-en/personal/chubb-future-achiever-savings-plan-2.html | K24: 历史逐请求检查时间。仅沿冻结的产品/版本处理明确缺件；不重跑已结案路线。 | L24: D1及历史
A25: SRC-HK-ca03c232c3 | B25: 香港 | C25: Fubon Life Insurance (Hong Kong) Company Limited | D25: 保险公司官方 | E25: www.fubonlife.com.hk | F25: 盈玥保險計劃 | G25: 46320 | H25: 可见公开页面未取得新增匹配主文；宣传册/优惠/支持件不等于主合同 | I25: =HYPERLINK("https://www.fubonlife.com.hk/life_hk/html/tc/products/treasure-prestige.html","https://www.fubonlife.com.hk/life_hk/html/tc/products/treasure-prestige.html") -> https://www.fubonlife.com.hk/life_hk/html/tc/products/treasure-prestige.html | K25: 历史逐请求检查时间。仅沿冻结的产品/版本处理明确缺件；不重跑已结案路线。 | L25: D1及历史
A26: SRC-HK-155493430c | B26: 香港 | C26: HSBC Life | D26: 保险公司官方 | E26: www.hsbc.com.hk | F26: HSBC EarlyIncome Deferred Annuity Plan | G26: 46320 | H26: 可见公开页面未取得新增匹配主文；宣传册/优惠/支持件不等于主合同 | I26: =HYPERLINK("https://www.hsbc.com.hk/insurance/products/savings-and-retirement/early-income-deferred-annuity/","https://www.hsbc.com.hk/insurance/products/savings-and-retirement/early-income-deferred-annuity/") -> https://www.hsbc.com.hk/insurance/products/savings-and-retirement/early-income-deferred-annuity/ | K26: 历史逐请求检查时间。仅沿冻结的产品/版本处理明确缺件；不重跑已结案路线。 | L26: D1及历史
A27: SRC-HK-e31a49cdc7 | B27: 香港 | C27: HSBC Life | D27: 保险公司官方 | E27: www.hsbc.com.hk | F27: HSBC Flourish Income Annuity Plan | G27: 46320 | H27: 可见公开页面未取得新增匹配主文；宣传册/优惠/支持件不等于主合同 | I27: =HYPERLINK("https://www.hsbc.com.hk/insurance/products/savings-and-retirement/flourish-income-annuity/","https://www.hsbc.com.hk/insurance/products/savings-and-retirement/flourish-income-annuity/") -> https://www.hsbc.com.hk/insurance/products/savings-and-retirement/flourish-income-annuity/ | K27: 历史逐请求检查时间。仅沿冻结的产品/版本处理明确缺件；不重跑已结案路线。 | L27: D1及历史
A28: SRC-HK-1f15ddfad2 | B28: 香港 | C28: HSBC Life | D28: 保险公司官方 | E28: www.hsbc.com.hk | F28: HSBC Income Goal Deferred Annuity Plan | G28: 46320 | H28: 可见公开页面未取得新增匹配主文；宣传册/优惠/支持件不等于主合同 | I28: =HYPERLINK("https://www.hsbc.com.hk/insurance/products/savings-and-retirement/income-goal-deferred-annuity/","https://www.hsbc.com.hk/insurance/products/savings-and-retirement/income-goal-deferred-annuity/") -> https://www.hsbc.com.hk/insurance/products/savings-and-retirement/income-goal-deferred-annuity/ | K28: 历史逐请求检查时间。仅沿冻结的产品/版本处理明确缺件；不重跑已结案路线。 | L28: D1及历史
A29: SRC-HK-12fb188f79 | B29: 香港 | C29: Hang Seng Insurance | D29: 保险公司官方 | E29: www.hangseng.com | F29: 「晉盛」延期年金人壽保險計劃 - 恒生銀行 | G29: 46320 | H29: 可见公开页面未取得新增匹配主文；宣传册/优惠/支持件不等于主合同 | I29: =HYPERLINK("https://www.hangseng.com/zh-hk/personal/insurance-mpf/retirement-wealth-education/fortunelife-deferred-annuity/","https://www.hangseng.com/zh-hk/personal/insurance-mpf/retirement-wealth-education/fortunelife-deferred-annuity/") -> https://www.hangseng.com/zh-hk/personal/insurance-mpf/retirement-wealth-education/fortunelife-deferred-annuity/ | K29: 历史逐请求检查时间。仅沿冻结的产品/版本处理明确缺件；不重跑已结案路线。 | L29: D1及历史
A30: SRC-HK-eef3efa20f | B30: 香港 | C30: Hang Seng Insurance | D30: 保险公司官方 | E30: www.hangseng.com | F30: 「聚息通」人壽保險計劃 | G30: 46320 | H30: 可见公开页面未取得新增匹配主文；宣传册/优惠/支持件不等于主合同 | I30: =HYPERLINK("https://www.hangseng.com/zh-hk/personal/insurance-mpf/retirement-wealth-education/income-power/","https://www.hangseng.com/zh-hk/personal/insurance-mpf/retirement-wealth-education/income-power/") -> https://www.hangseng.com/zh-hk/personal/insurance-mpf/retirement-wealth-education/income-power/ | K30: 历史逐请求检查时间。仅沿冻结的产品/版本处理明确缺件；不重跑已结案路线。 | L30: D1及历史
A31: SRC-HK-128249f83d | B31: 香港 | C31: Hong Kong Life Insurance Limited | D31: 保险公司官方 | E31: www.hklife.com.hk | F31: Wealth Global Multi-Currency Insurance Plan | G31: 46320 | H31: 可见公开页面未取得新增匹配主文；宣传册/优惠/支持件不等于主合同 | I31: =HYPERLINK("https://www.hklife.com.hk/en/products/personal-insurance/savings-plan/wealth-global-multi-currency-insurance-plan/index.html","https://www.hklife.com.hk/en/products/personal-insurance/savings-plan/wealth-global-multi-currency-insurance-plan/index.html") -> https://www.hklife.com.hk/en/products/personal-insurance/savings-plan/wealth-global-multi-currency-insurance-plan/index.html | K31: 历史逐请求检查时间。仅沿冻结的产品/版本处理明确缺件；不重跑已结案路线。 | L31: D1及历史
A32: SRC-HK-204b85559d | B32: 香港 | C32: YF Life | D32: 保险公司官方 | E32: www.yflife.com | F32: 萬通多元教育儲蓄計劃 | G32: 46320 | H32: 可见公开页面未取得新增匹配主文；宣传册/优惠/支持件不等于主合同 | I32: =HYPERLINK("https://www.yflife.com/tc/product/savings/my-flexi-generations-saver/","https://www.yflife.com/tc/product/savings/my-flexi-generations-saver/") -> https://www.yflife.com/tc/product/savings/my-flexi-generations-saver/ | K32: 历史逐请求检查时间。仅沿冻结的产品/版本处理明确缺件；不重跑已结案路线。 | L32: D1及历史
A33: SRC-HK-d9f168be97 | B33: 香港 | C33: Zurich Life Insurance (Hong Kong) Limited | D33: 保险公司官方 | E33: life.zurich.com.hk | F33: Swiss Prime Savings Insurance Plan | G33: 46320 | H33: 可见公开页面未取得新增匹配主文；宣传册/优惠/支持件不等于主合同 | I33: =HYPERLINK("https://life.zurich.com.hk/en/products/swiss-prime-savings-insurance-plan/","https://life.zurich.com.hk/en/products/swiss-prime-savings-insurance-plan/") -> https://life.zurich.com.hk/en/products/swiss-prime-savings-insurance-plan/ | K33: 历史逐请求检查时间。仅沿冻结的产品/版本处理明确缺件；不重跑已结案路线。 | L33: D1及历史
A34: SRC-HK-90272692ff | B34: 香港 | C34: AIA 友邦香港 | D34: 保险公司官方 | E34: www.aia.com.hk | F34: AIA延期年金計劃2 | G34: 46320 | H34: 页面可访问；所查可见链接未取得匹配主文；页面提示可按需索取 | I34: =HYPERLINK("https://www.aia.com.hk/en/products/save/aia-deferred-annuity-plan-2.html","https://www.aia.com.hk/en/products/save/aia-deferred-annuity-plan-2.html") -> https://www.aia.com.hk/en/products/save/aia-deferred-annuity-plan-2.html | K34: 历史本轮记录日期；非今日重访。仅沿冻结的产品/版本处理明确缺件；不重跑已结案路线。 | L34: D1及历史
A35: SRC-HK-4d6dc4e758 | B35: 香港 | C35: AIA 友邦香港 | D35: 保险公司官方 | E35: www.aia.com.hk | F35: GlobalFlexi Savings Insurance Plan | G35: 46320 | H35: 页面可访问；所查可见链接未取得匹配主文；页面提示可按需索取 | I35: =HYPERLINK("https://www.aia.com.hk/en/products/save/global-flexi.html","https://www.aia.com.hk/en/products/save/global-flexi.html") -> https://www.aia.com.hk/en/products/save/global-flexi.html | K35: 历史本轮记录日期；非今日重访。仅沿冻结的产品/版本处理明确缺件；不重跑已结案路线。 | L35: D1及历史
A36: SRC-HK-fc65524559 | B36: 香港 | C36: AIA 友邦香港 | D36: 保险公司官方 | E36: www.aia.com.hk | F36: Global Power Multi-Currency Savings Insurance Plan 3 | G36: 46320 | H36: 页面可访问；所查可见链接未取得匹配主文；页面提示可按需索取 | I36: =HYPERLINK("https://www.aia.com.hk/en/products/save/global-power-3.html","https://www.aia.com.hk/en/products/save/global-power-3.html") -> https://www.aia.com.hk/en/products/save/global-power-3.html | K36: 历史本轮记录日期；非今日重访。仅沿冻结的产品/版本处理明确缺件；不重跑已结案路线。 | L36: D1及历史
A37: SRC-HK-5184343d26 | B37: 香港 | C37: AIA 友邦香港 | D37: 保险公司官方 | E37: www.aia.com.hk | F37: 「活然人生」保險計劃 | G37: 46320 | H37: 页面可访问；所查可见链接未取得匹配主文；页面提示可按需索取 | I37: =HYPERLINK("https://www.aia.com.hk/en/products/save/prosperlife.html","https://www.aia.com.hk/en/products/save/prosperlife.html") -> https://www.aia.com.hk/en/products/save/prosperlife.html | K37: 历史本轮记录日期；非今日重访。仅沿冻结的产品/版本处理明确缺件；不重跑已结案路线。 | L37: D1及历史
A38: SRC-HK-6da6f21312 | B38: 香港 | C38: AIA 友邦香港 | D38: 保险公司官方 | E38: www.aia.com.hk | F38: Wealth Flexi Savings Insurance Plan | G38: 46320 | H38: 页面可访问；所查可见链接未取得匹配主文；页面提示可按需索取 | I38: =HYPERLINK("https://www.aia.com.hk/en/products/save/wealth-flexi","https://www.aia.com.hk/en/products/save/wealth-flexi") -> https://www.aia.com.hk/en/products/save/wealth-flexi | K38: 历史本轮记录日期；非今日重访。仅沿冻结的产品/版本处理明确缺件；不重跑已结案路线。 | L38: D1及历史
A39: SRC-HK-550167b5ea | B39: 香港 | C39: Manulife 宏利香港 | D39: 保险公司官方 | E39: www.manulife.com.hk | F39: 宏浚傳承保障計劃 | G39: 46320 | H39: 页面可访问；所查可见链接未取得匹配主文 | I39: =HYPERLINK("https://www.manulife.com.hk/en/individual/products/save/savings/future-assure.html","https://www.manulife.com.hk/en/individual/products/save/savings/future-assure.html") -> https://www.manulife.com.hk/en/individual/products/save/savings/future-assure.html | K39: 历史本轮记录日期；非今日重访。仅沿冻结的产品/版本处理明确缺件；不重跑已结案路线。 | L39: D1及历史
A40: SRC-HK-5eb777bde3 | B40: 香港 | C40: Manulife 宏利香港 | D40: 保险公司官方 | E40: www.manulife.com.hk | F40: 宏摯家傳承保險計劃 | G40: 46320 | H40: 页面可访问；所查可见链接未取得匹配主文；页面提示可按需索取 | I40: =HYPERLINK("https://www.manulife.com.hk/en/individual/products/save/savings/genesis-centurion.html","https://www.manulife.com.hk/en/individual/products/save/savings/genesis-centurion.html") -> https://www.manulife.com.hk/en/individual/products/save/savings/genesis-centurion.html | K40: 历史本轮记录日期；非今日重访。仅沿冻结的产品/版本处理明确缺件；不重跑已结案路线。 | L40: D1及历史
...

Sheet 验收口径
A1: 项目 | B1: 口径／动作 | C1: 验收必备 | D1: 计数边界
A2: 冻结范围 | B2: 原258工单及历史数据保留；B28新增1条状态纠正工单，累计259。 | C2: 任务ID、原始ID及来源ID保持稳定。各批冻结期初不写成验收结果。 | D2: 259为限定工单，不是独立产品。B28无新增全文，窄核45页不计入4250全审页。
A3: 证据验收 | B3: 证据验收与内容、文件主角色、产品主文可得、当前包齐备及严格通过分别记录。 | C3: 复核通过、证据非空、有效处理日及唯一冻结范围匹配。 | D3: 只有已验收明确增量纳入。部分语言审读、通用组件和材料映射不得自动升格。
A4: 完整主文 | B4: 正文应具备可读完整内容、连续页序与准确身份，不以文件名、宣传册、文本提取成功或可下载代替。 | C4: 逐页页码及内容记录；法律主体、渠道、文档角色、版本或未知标记；依赖组件与缺件。 | D4: 严格通过按文件计，不直接等于独立产品或整套合同齐备。
A5: 版本与采用 | B5: 正文印载版本、官方当前采用与产品现售状态分别核验。URL目录年份不能替代版次。 | C5: 精确版本／组件及明确采用依据。没有证据时保持未知。 | D5: Home Protector 360 与 Basic 分开。FOCUS 21物理页／24页脚疑点未解除前不得升级完整。
A6: 马来西亚文档 | B6: D1冻结5份原件114页，B2另核5份原件187页，不重复计数。Assurance与Takaful分开，团体与个人不混用。 | C6: 按原始文档身份和哈希核全文；保留英文／马来文判断依据及疑点页码。 | D6: Master 文档核验不等于具名产品锁定、现行主文采用或整套齐备。
A7: 来源日期 | B7: 各批均于2026-10-26冻结。历史来源保持原检查日；新公开响应观测日另列，不把全文审读日当作重新取得日。 | C7: 新执行证据另记实际访问／核验时间、官方 URL 和结果。 | D7: v89 历史原件、全文、严格通过与隔离文件，不计入本批新增。
A8: 公开入口边界 | B8: 只检查固定范围的公开官方入口及明确匹配来源。遇403、登录、验证码或WAF停止该入口。 | C8: 保留已查路线、访问结果和停止原因；不猜路径、不绕过限制、不外联、不搜索真实个人保单。 | D8: 受阻或未取得保留原任务，不删除、不升级为已齐备。
A9: 未知与零 | B9: 缺少经核验的统计时留空并注明。零仅用于已确认范围内的真实零。 | C9: 列明统计对象、单位、来源和分母。家族范围不是全市场产品数。 | D9: 全市场独立产品分母尚未核定；不据此计算全市场覆盖率。
A12: 校验项 | B12: 实际值 | C12: 冻结基数 | D12: 判定
A13: 地区行数 | B13: =COUNTA('12地区基线'!A2:A13) -> 12 | C13: 12 | D13: =IF(B13=C13,"一致","需检查增删") -> 一致
A14: 任务行数 | B14: =COUNTA(首批固定任务!A2:A109) -> 108 | C14: 108 | D14: =IF(B14=C14,"一致","需检查增删") -> 一致
A15: 来源行数 | B15: =COUNTA(保司与来源!A2:A243) -> 242 | C15: 242 | D15: =IF(B15=C15,"一致","需检查增删") -> 一致
A16: 正式文件合计 | B16: =SUM('12地区基线'!D2:D13) -> 4710 | C16: 4710 | D16: =IF(B16=C16,"一致","需检查增删") -> 一致
A17: 已全文审阅合计 | B17: =SUM('12地区基线'!E2:E13) -> 2245 | C17: 2245 | D17: =IF(B17=C17,"一致","需检查增删") -> 一致
A18: 严格通过合计 | B18: =SUM('12地区基线'!F2:F13) -> 411 | C18: 411 | D18: =IF(B18=C18,"一致","需检查增删") -> 一致
A19: 隔离文件合计 | B19: =SUM('12地区基线'!G2:G13) -> 51 | C19: 51 | D19: =IF(B19=C19,"一致","需检查增删") -> 一致
A21: 冻结任务ID | B21: 冻结表出现次数 | C21: 执行表出现次数 | D21: 范围判定
A22: D1-HK-001 | B22: =COUNTIFS(首批固定任务!$A$2:$A$24,A22) -> 1 | C22: =COUNTIFS(本批执行结果!$A$2:$A$24,A22) -> 1 | D22: =IF(AND(B22=1,C22=1),"一致","缺范围或重复") -> 一致
A23: D1-HK-002 | B23: =COUNTIFS(首批固定任务!$A$2:$A$24,A23) -> 1 | C23: =COUNTIFS(本批执行结果!$A$2:$A$24,A23) -> 1 | D23: =IF(AND(B23=1,C23=1),"一致","缺范围或重复") -> 一致
A24: D1-HK-003 | B24: =COUNTIFS(首批固定任务!$A$2:$A$24,A24) -> 1 | C24: =COUNTIFS(本批执行结果!$A$2:$A$24,A24) -> 1 | D24: =IF(AND(B24=1,C24=1),"一致","缺范围或重复") -> 一致
A25: D1-HK-004 | B25: =COUNTIFS(首批固定任务!$A$2:$A$24,A25) -> 1 | C25: =COUNTIFS(本批执行结果!$A$2:$A$24,A25) -> 1 | D25: =IF(AND(B25=1,C25=1),"一致","缺范围或重复") -> 一致
A26: D1-SG-001 | B26: =COUNTIFS(首批固定任务!$A$2:$A$24,A26) -> 1 | C26: =COUNTIFS(本批执行结果!$A$2:$A$24,A26) -> 1 | D26: =IF(AND(B26=1,C26=1),"一致","缺范围或重复") -> 一致
A27: D1-SG-002 | B27: =COUNTIFS(首批固定任务!$A$2:$A$24,A27) -> 1 | C27: =COUNTIFS(本批执行结果!$A$2:$A$24,A27) -> 1 | D27: =IF(AND(B27=1,C27=1),"一致","缺范围或重复") -> 一致
A28: D1-SG-003 | B28: =COUNTIFS(首批固定任务!$A$2:$A$24,A28) -> 1 | C28: =COUNTIFS(本批执行结果!$A$2:$A$24,A28) -> 1 | D28: =IF(AND(B28=1,C28=1),"一致","缺范围或重复") -> 一致
A29: D1-MY-001 | B29: =COUNTIFS(首批固定任务!$A$2:$A$24,A29) -> 1 | C29: =COUNTIFS(本批执行结果!$A$2:$A$24,A29) -> 1 | D29: =IF(AND(B29=1,C29=1),"一致","缺范围或重复") -> 一致
A30: D1-MY-002 | B30: =COUNTIFS(首批固定任务!$A$2:$A$24,A30) -> 1 | C30: =COUNTIFS(本批执行结果!$A$2:$A$24,A30) -> 1 | D30: =IF(AND(B30=1,C30=1),"一致","缺范围或重复") -> 一致
A31: D1-MY-003 | B31: =COUNTIFS(首批固定任务!$A$2:$A$24,A31) -> 1 | C31: =COUNTIFS(本批执行结果!$A$2:$A$24,A31) -> 1 | D31: =IF(AND(B31=1,C31=1),"一致","缺范围或重复") -> 一致
A32: D1-MY-004 | B32: =COUNTIFS(首批固定任务!$A$2:$A$24,A32) -> 1 | C32: =COUNTIFS(本批执行结果!$A$2:$A$24,A32) -> 1 | D32: =IF(AND(B32=1,C32=1),"一致","缺范围或重复") -> 一致
A33: D1-MY-005 | B33: =COUNTIFS(首批固定任务!$A$2:$A$24,A33) -> 1 | C33: =COUNTIFS(本批执行结果!$A$2:$A$24,A33) -> 1 | D33: =IF(AND(B33=1,C33=1),"一致","缺范围或重复") -> 一致
... A44: B2-KH-002 | B44: =COUNTIFS(首批固定任务!$A$2:$A$24,A44) -> 1 | C44: =COUNTIFS(本批执行结果!$A$2:$A$24,A44) -> 1 | D44: =IF(AND(B44=1,C44=1),"一致","缺范围或重复") -> 一致
A46: B2内容分层 | B46: 6份现存全文205页。4份主文角色确认后仍待核验。 | C46: 32页EASYCare视觉结构证据独立保存，不计全文。 | D46: 新原件0、严格新增0、独立产品缺口关闭0。
A47: D1/B2历史发布 | B47: 两批已发布至线上版本115。网站已更新第二批核验状态。 | C47: 正式原件4713、公开4662、全文2256、部分核验14、严格411、隔离51。 | D47: B2新增6份全文已在线。原件与详审证据私有留存。
A48: 后续批次 | B48: B3/B4/B5/B6见新增验收与审计区；不把旧候选状态视为当前。 | C48: 历史23、67、108、198、203、210、218、238、258保留；B28追加后259。 | D48: 完整原始文件数、全文、角色、严格和产品闭合分层计量。
A50: 使用权限 | B50: 全文审读表示内容检查，不代表允许复制、再发布或商业复用。 | C50: 受限文件不提供可自动使用的提取文本。 | D50: 原件及审计历史保持。
A53: 追加批次审计 | B53: 冻结表次数 | C53: 执行表次数 | D53: 范围判定
A54: B3-MY-001 | B54: =COUNTIFS(首批固定任务!$A$2:$A$68,A54) -> 1 | C54: =COUNTIFS(本批执行结果!$A$2:$A$68,A54) -> 1 | D54: =IF(AND(B54=1,C54=1),"一致","缺范围或重复") -> 一致
A55: B3-MY-002 | B55: =COUNTIFS(首批固定任务!$A$2:$A$68,A55) -> 1 | C55: =COUNTIFS(本批执行结果!$A$2:$A$68,A55) -> 1 | D55: =IF(AND(B55=1,C55=1),"一致","缺范围或重复") -> 一致
A56: B3-MY-003 | B56: =COUNTIFS(首批固定任务!$A$2:$A$68,A56) -> 1 | C56: =COUNTIFS(本批执行结果!$A$2:$A$68,A56) -> 1 | D56: =IF(AND(B56=1,C56=1),"一致","缺范围或重复") -> 一致
A57: B3-MY-004 | B57: =COUNTIFS(首批固定任务!$A$2:$A$68,A57) -> 1 | C57: =COUNTIFS(本批执行结果!$A$2:$A$68,A57) -> 1 | D57: =IF(AND(B57=1,C57=1),"一致","缺范围或重复") -> 一致
...

Sheet MY身份与材料
A1: MY限定合同身份与材料关系
A2: 仅2个身份工作单、4个既审合同版本及31项材料关系。不是全市场产品分母；不新增原件、全文、主文、严格或产品闭合。
A4: 原始ID | B4: 法律主体 | C4: 正文计划名 | D4: 合同号 | E4: 已审版本依据 | F4: 版本登记ID | G4: 历史主文角色 | H4: 当前精确采用 | I4: 当前在售 | J4: 当前公开合同包
A5: MY-SUN-006 | B5: Sun Life Malaysia Assurance Berhad | C5: Cash Plus Assurance | D5: CPA0613 | E5: 2015-01-01 / 2020-07-01 / 2025-07-01 批单集合；非现行采用证明 | F5: MY-CV-db45e5380bd10dcf4637ad23 | G5: 已核（历史） | H5: 未核定（非否定） | I5: 未核定（非否定） | J5: 未确认齐备
A6: MY-SUN-008 | B6: Sun Life Malaysia Assurance Berhad | C6: Credit Protector Plus | D6: CPP0813 | E6: 2016-04-01 / 2020-07-01 / 2021-05-28 / 2025-07-01 批单集合；非现行采用证明 | F6: MY-CV-58044f828aef3206e86806c8 | G6: 已核（历史） | H6: 未核定（非否定） | I6: 未核定（非否定） | J6: 未确认齐备
A7: MY-SUN-002 | B7: Sun Life Malaysia Assurance Berhad | C7: Biz Shield | D7: BIZS0914 | E7: 2015-01-01 / 2020-07-01 / 2025-07-01 批单集合；非现行采用证明 | F7: MY-CV-662b30a1b4203ee9442d934b | G7: 非主文（历史） | H7: 未核定（非否定） | I7: 未核定（非否定） | J7: 未确认齐备
A8: MY-SUN-036 | B8: Sun Life Malaysia Takaful Berhad | C8: Biz Shield-i | D8: BSI0317 | E8: 2019-07-01 / 2020-07-01 / 2025-07-01 批单集合；非现行采用证明 | F8: MY-CV-b69be7a48e4192e2e2b1bb23 | G8: 已核（历史） | H8: 未核定（非否定） | I8: 未核定（非否定） | J8: 未确认齐备
A10: 材料关系 ≠ 实际采用：附表、组件、批单及目录关联分别登记；空白／未核定不能作通配合并，Assurance与Takaful分开。
A12: 原始ID | B12: 材料角色 | C12: 材料标签 | D12: 组件编号 | E12: 物理页／范围 | F12: 原件中存在 | G12: 依赖分类 | H12: 关联性质 | I12: 当前采用／现售 | J12: 证据索引
A13: MY-SUN-006 | B13: 既审具名主合同原件 | C13: Cash Plus Assurance Master Policy | D13: CPA0613 | E13: 34 | F13: 已核存在 | G13: A：含附表性质未解依赖 | H13: 已审材料组成关系 | I13: 均未核定，不因关联而升级 | J13: REL-062dc678dba03d8de6c6；EV-3161e8a4d95fd95e / EV-301f3823904fefeb / EV-787f09b2a1442c84
A14: MY-SUN-006 | B14: 现存标准附件组 | C14: CPA002 / CPA003 / CPA004 / CPA005 | D14: CPA002 / CPA003 / CPA004 / CPA005 | E14: 未单独计页 | F14: 已核存在 | G14: A：公共通用组件 | H14: 已审材料组成关系 | I14: 均未核定，不因关联而升级 | J14: REL-b0cc250fab35ceeb1e6c；EV-083bf1d337cc4a02
A15: MY-SUN-006 | B15: 具日期批单 | C15: sanctions endorsement effective2025-07-01 | D15: 未核定 | E15: 未单独计页 | F15: 已核存在 | G15: A：公共通用组件 | H15: 已审材料组成关系 | I15: 均未核定，不因关联而升级 | J15: REL-b1a78f3e3b752da0cbbf；EV-e7c6abb191a1a3bb
